Workbook
Name Slicer_TL: #N/A
Name Slicer_TL1: #N/A
Name Slicer_TL7: #N/A

Sheet Dashboard
B1: Retention Performance | P1: Feb
P2: Working Days | Q2: 31
B3: Retention Queue Performance | P3: Days Worked | Q3: 18
B4: KPI's | C4: Last week Performance | F4: Last Week Sans Monday | I4: MTD Performance Calls Ans | L4: Last Month Comparison
C5: Calls | D5: Service Level | E5: ABA% | F5: Calls | G5: Service Level | H5: ABA% | I5: Calls | J5: Service Level | K5: ABA% | L5: Calls | M5: Service Level | N5: ABA%
B6: Retention Queue Performance | C6: 1456 | D6: 0.95 | E6: 0 | F6: 1122 | G6: 0.95 | H6: 0 | I6: 6630 | J6: 0.83 | K6: 0.06 | L6: 6862 | M6: 0.77 | N6: 0.08
B7: Service | C7: 10 | D7: 0.8 | E7: 0 | F7: 10 | G7: 0.8 | H7: 0 | I7: 2041 | J7: 0.72 | K7: 0.1 | L7: 69 | M7: 0.8 | N7: 0.02 | P7: Power BI MTD
B8: Collections | C8: 7 | D8: 0.71 | E8: 0.02 | F8: 7 | G8: 0.71 | H8: 0.02 | I8: 28 | J8: 0.79 | K8: 0 | L8: 85 | M8: 0.81 | N8: 0.08 | P8: ACH - 30.8% | R8: Telreg Skilled Conv - 19.3%
C10: MOM Comparison | I10: LW Monday Performance | P10: QA MTD
C11: MTD | D11: EOM Estimate | E11: Last Month | F11: MOM Change | J11: Calls Answered | K11: Calls Handled | L11: Service Level | M11: ABA% | N11: Calls Abandoned | P11: AVG | Q11: # of Evals | S11: Crit
C12: Calls | D12: Calls | E12: Calls | F12: Calls | I12: Retention | J12: 334 | K12: 334 | L12: 0.87 | M12: 0.04 | N12: 27 | P12: 0.95142857 | Q12: 35 | S12: 0.98639457
B13: Retention Queue Performance | C13: 6630 | D13: 11418.333 | E13: 6862 | F13: 4556.3333 | I13: Telreg | J13: 0 | K13: 0 | L13: 0 | M13: 0 | N13: 0
B14: Service | C14: 2041 | D14: 3515.0556 | E14: 69 | F14: 3446.0556 | I14: Collections | J14: 0 | K14: 0 | L14: 0.86 | M14: 0 | N14: 0
B15: Collections | C15: 28 | D15: 48.222222 | E15: 85 | F15: -36.777778 | G15: % Difference | I15: Totals | J15: 334 | K15: 334 | L15: 0.57666667 | M15: 0.013333333 | N15: 27
B16: Combined | C16: 8699 | D16: 14981.611 | E16: 7016 | F16: 7965.6111 | G16: 2.1353494 | I16: % of TV | J16: 0.22674813
B20: KPI Retention | C20: Last Week | F20: Current Week | I20: MTD | L20: Previous Month
B21: Column1 | C21: Calls | D21: Sales | E21: Conversion | F21: Calls2 | G21: Sales3 | H21: Conversion4 | I21: Calls5 | J21: Sales6 | K21: Conversion7 | L21: Calls8 | M21: Sales9 | N21: Conversion2
B22: Service | C22: 11 | D22: 20 | E22: 1.8181818 | F22: 0 | G22: 3 | H22: #DIV/0! | I22: 2041 | J22: 198 | K22: 0.097011269 | L22: 69 | M22: 62 | N22: 0.89855072
B23: OOW | C23: 1467 | D23: 19 | E23: 0.012951602 | F23: 1238 | G23: 17 | H23: 0.013731826 | I23: 8671 | J23: 142 | K23: 0.016376427 | L23: 6931 | M23: 81 | N23: 0.011686625
B24: Retention | C24: 1456 | D24: 1155 | E24: 0.79326923 | F24: 1238 | G24: 1033 | H24: 0.83441034 | I24: 6630 | J24: 5088 | K24: 0.76742081 | L24: 6862 | M24: 5367 | N24: 0.78213349
K26: Month | P26: Prev | R26: Current
B27: Outliers Ret | C27: Prev Month | D27: MTD | E27: Cur Week | F27: Lst Week | G27: Action | H27: Goal | I27: Stage | K27: Agents | L27: Canc Rate | M27: Save % | N27: Serv Con | P27: Agent | Q27: ININ Wrap | R27: Agent | S27: ININ Wrap
B28: Douglas Barnes | C28: 0.67961165 | D28: 0.70445344 | E28: 0.87179487 | F28: 1.4285714 | K28: Khadijah Young | L28: 0.69950739 | M28: 1.1551724 | N28: 0.058524173 | P28: Douglas Barnes | Q28: 9 | R28: Chasady Parker | S28: 26
B29: Amy Smiley | C29: 0.64684015 | D29: 0.69 | E29: 0.65116279 | F29: 0.84615385 | K29: Regina Watson | L29: 0.62751678 | M29: 0.99328859 | N29: 0.30263158 | P29: Khadijah Young | Q29: 6 | R29: Angelica Gonzalez | S29: 7
C30: 0 | D30: 0 | E30: 0 | F30: 0 | K30: Angelica Gonzalez | L30: 0.69555035 | M30: 0.94964871 | N30: 0.15135135 | P30: Chasady Parker | Q30: 5 | R30: Mohamed Bayoumy | S30: 5
C31: 0 | D31: 0 | E31: 0 | F31: 0 | K31: Larry Moorehead | L31: 0.77469136 | M31: 0.73148148 | N31: 0.035598706 | P31: Chanetta Gant | Q31: 4 | R31: Regina Watson | S31: 5
C32: 0 | D32: 0 | E32: 0 | F32: 0 | K32: Mohamed Bayoumy | L32: 0.74178935 | M32: 0.73046433 | N32: 0.11428571 | P32: Angelica Gonzalez | Q32: 3 | R32: Douglas Barnes | S32: 3
K33: Margaret Reddy | L33: 0.95631068 | M33: 0.70873786 | N33: 0.070921986 | P33: Amy Smiley | Q33: 3 | R33: Perry Young III | S33: 3
B34: Outlier Cancellation | C34: Prev Month | D34: MTD | E34: Cur Week | F34: Lst Week | G34: Action | H34: Goal | I34: Stage | K34: Douglas Barnes | L34: 0.93927126 | M34: 0.70445344 | N34: 0.016393443 | P34: Mohamed Bayoumy | Q34: 3 | R34: Chanetta Gant | S34: 2
B35: Douglas Barnes | C35: 0.88673139 | D35: 0.93927126 | E35: 1.0512821 | F35: 0.71428571 | G35: pm | H35: 0.7 | K35: Amy Smiley | L35: 0.77666667 | M35: 0.69 | N35: 0 | P35: Larry Moorehead | Q35: 2 | R35: Matthew Livingstone | S35: 1
B36: Larry Moorehead | C36: 0.81849315 | D36: 0.77469136 | E36: 1.0181818 | F36: 0 | G36: pm | H36: 0.7 | K36: Chanetta Gant | L36: 0.78615071 | M36: 0.67617108 | N36: 0.51851852 | P36: Perry Young III | Q36: 1 | R36: Khadijah Young | S36: 0
B37: Perry Young | C37: 0.85487805 | D37: 1.003886 | E37: 1.2594937 | F37: 0.79435484 | G37: pm | H37: 0.7 | K37: Matthew Livingstone | L37: 0.88091603 | M37: 0.64427481 | N37: 0 | P37: Margaret Reddy | Q37: 1 | R37: Larry Moorehead | S37: 0
B38: Margaret Reddy | C38: 0.8562753 | D38: 0.95631068 | E38: 1.0309278 | F38: 0.82352941 | G38: pm | H38: 0.7 | K38: Perry Young | L38: 1.003886 | M38: 0.62953368 | N38: 0 | P38: Regina Watson | Q38: 0 | R38: Margaret Reddy | S38: 0
K39: Chasady Parker | L39: 0.38374718 | M39: 0.55756208 | N39: 0.057971014 | P39: Matthew Livingstone | Q39: 0 | R39: Amy Smiley | S39: 0
K40: Christina Johnson | L40: 0 | M40: 0 | N40: 0 | P40: Christina Johnson | Q40: 0 | R40: Christina Johnson | S40: 0
B41: Absenteeism | K41: Week
B42: Previous MTD | F42: MTD | K42: Agents | L42: Canc Rate | M42: Save % | N42: IW S2C
B43: Sales - Tel Reg | F43: Sales - Tel Reg | K43: Regina Watson | L43: 0.55833333 | M43: 1.225 | N43: 0
B44: Total Schedule Time | C44: 2319.15 | F44: Total Schedule Time | G44: 2194.1167 | K44: Angelica Gonzalez | L44: 0.7983871 | M44: 0.70967742 | N44: 0
B45: On Queue Time / Nesting | C45: 1690.65 | D45: 0.72899554 | F45: On Queue Time / Nesting | G45: 1411.0333 | H45: 0.64309859 | K45: Khadijah Young | L45: 0.63333333 | M45: 0.94444444 | N45: 0
...

Sheet Shrink
A1: Agent Name | B1: Activity Code Name | C1: Description | D1: Is Paid | E1: Length In Minutes | F1: Start (New_York) | G1: End (New_York)
A2: Amy Smiley | B2: Vacation | C2: Gary - ticket # 13495- PTO for March 30th, 31st , April 1st,2nd,3rd - wfm approved | D2: Yes | E2: 450 | F2: 46113.417 | G2: 46113.729 | J2: Total Schedule Time | K2: =SUM(K3:K36) -> 203694 | N2: Sales - Tel Reg
A3: Amy Smiley | B3: End of shift | D3: No | E3: 60 | F3: 46113.729 | G3: 46113.771 | J3: Vacation | K3: =SUMIF($B$2:$B$100000,"Vacation",$E$2:$E$100000) -> 4020 | N3: Total Schedule Time | O3: =K2/60 -> 3394.9
A4: Amy Smiley | B4: Vacation | C4: Gary - ticket # 13495- PTO for March 30th, 31st , April 1st,2nd,3rd - wfm approved | D4: Yes | E4: 450 | F4: 46114.417 | G4: 46114.729 | J4: On Queue | K4: =SUMIF($B$2:$B$100000,"On Queue",$E$2:$E$100000) -> 125088 | N4: On Queue Time / Nesting | O4: =(K4+K18)/60 -> 2084.8 | P4: =O4/$O$3 -> 0.61409762
A5: Amy Smiley | B5: End of shift | D5: No | E5: 60 | F5: 46114.729 | G5: 46114.771 | J5: VTO | K5: =SUMIF($B$2:$B$100000,"VTO",$E$2:$E$100000) -> 428 | N5: PTO | O5: =K3/60 -> 67 | P5: =O5/$O$3 -> 0.019735486
A6: Amy Smiley | B6: Vacation | C6: Gary - ticket # 13495- PTO for March 30th, 31st , April 1st,2nd,3rd - wfm approved | D6: Yes | E6: 330 | F6: 46115.375 | G6: 46115.604 | J6: MATO | K6: =SUMIF($B$2:$B$100000,"MATO",$E$2:$E$100000) -> 0 | N6: Break | O6: =K19/60 -> 160.45 | P6: =O6/$O$3 -> 0.04726207
A7: Amy Smiley | B7: End of shift | D7: No | E7: 60 | F7: 46115.604 | G7: 46115.646 | J7: Weather - Site Closure | K7: =SUMIF($B$2:$B$100000,"Weather - Site Closure",$E$2:$E$100000) -> 0 | N7: Lunch | O7: =K20/60 -> 165.31667 | P7: =O7/$O$3 -> 0.048695592
A8: Amy Smiley | B8: Absent | D8: No | E8: 330 | F8: 46118.375 | G8: 46118.604 | J8: NCNS | K8: =SUMIF($B$2:$B$100000,"NCNS",$E$2:$E$100000) -> 2184 | N8: VTO / MATO | O8: =(K5+K6)/60 -> 7.1333333 | P8: =O8/$O$3 -> 0.002101191
A9: Amy Smiley | B9: End of shift | D9: No | E9: 60 | F9: 46118.604 | G9: 46118.646 | J9: Absent | K9: =SUMIF($B$2:$B$100000,"Absent ",$E$2:$E$100000) -> 10680 | N9: Absenteeism | O9: =(K8+K9+K10+K11+K12+K13)/60 -> 376.78333 | P9: =O9/$O$3 -> 0.11098511
A10: Amy Smiley | B10: Absent | D10: No | E10: 330 | F10: 46119.375 | G10: 46119.604 | J10: Late | K10: =SUMIF($B$2:$B$100000,"Late",$E$2:$E$100000) -> 1400 | N10: LOA / Bereavment | O10: =(K16+K17)/60 -> 153 | P10: =O10/$O$3 -> 0.045067601
A11: Amy Smiley | B11: End of shift | D11: No | E11: 60 | F11: 46119.604 | G11: 46119.646 | J11: Left Early | K11: =SUMIF($B$2:$B$100000,"Left Early",$E$2:$E$100000) -> 2906 | N11: Scheduled OT | O11: =K14/60 -> 6 | P11: =O11/$O$3 -> 0.0017673569
A12: Amy Smiley | B12: On Queue | D12: Yes | E12: 120 | F12: 46120.417 | G12: 46120.5 | J12: Shift Abandoned | K12: =SUMIF($B$2:$B$100000,"Shift Abandoned",$E$2:$E$100000) -> 4417 | N12: Make Up Time | O12: =K15/60 -> 0 | P12: =O12/$O$3 -> 0
A13: Amy Smiley | B13: Break | D13: Yes | E13: 15 | F13: 46120.5 | G13: 46120.51 | J13: Termed | K13: =SUMIF($B$2:$B$100000,"Termed",$E$2:$E$100000) -> 1020 | N13: Coaching / Meeting / Team Huddle | O13: =(K21+K22+K23)/60 -> 54.666667 | P13: =O13/$O$3 -> 0.016102585
A14: Amy Smiley | B14: On Queue | D14: Yes | E14: 12 | F14: 46120.51 | G14: 46120.519 | J14: Scheduled OT | K14: =SUMIF($B$2:$B$100000,"Scheduled OT",$E$2:$E$100000) -> 360 | N14: SME / Peer Coaching | O14: =(K24+K25)/60 -> 2.5 | P14: =O14/$O$3 -> 0.00073639872
A15: Amy Smiley | B15: Coaching | C15: William Coad Ticket # 14609:Coaching 15 mins 1230pm | D15: Yes | E15: 15 | F15: 46120.519 | G15: 46120.529 | J15: Make Up Time | K15: =SUMIF($B$2:$B$100000,"MUT",$E$2:$E$100000) -> 0 | N15: Back Office / Off Queue | O15: =(K26+K27)/60 -> 0 | P15: =O15/$O$3 -> 0
A16: Amy Smiley | B16: No ticket | D16: Yes | E16: 6 | F16: 46120.529 | G16: 46120.533 | J16: LOA | K16: =SUMIF($B$2:$B$100000,"LOA",$E$2:$E$100000) -> 8670 | N16: Training | O16: =(K29+K30)/60 -> 252.85 | P16: =O16/$O$3 -> 0.074479366
A17: Amy Smiley | B17: On Queue | D17: Yes | E17: 87 | F17: 46120.533 | G17: 46120.594 | J17: Bereavement | K17: =SUMIF($B$2:$B$100000,"Bereavement",$E$2:$E$100000) -> 510 | N17: Outbound Calls | O17: =(K31+K32)/60 -> 5.2833333 | P17: =O17/$O$3 -> 0.001556256
A18: Amy Smiley | B18: Meal | D18: No | E18: 30 | F18: 46120.594 | G18: 46120.615 | J18: Nesting | K18: =SUMIF($B$2:$B$100000,"Nesting",$E$2:$E$100000) -> 0 | N18: System Issues | O18: =(K33+K34)/60 -> 37.383333 | P18: =O18/$O$3 -> 0.011011615
A19: Amy Smiley | B19: On Queue | D19: Yes | E19: 165 | F19: 46120.615 | G19: 46120.729 | J19: Break | K19: =SUMIF($B$2:$B$100000,"Break",$E$2:$E$100000) -> 9627 | N19: No Ticket Time | O19: =(K35+K36)/60 -> 21.733333 | P19: =O19/$O$3 -> 0.0064017595
A20: Amy Smiley | B20: End of shift | D20: No | E20: 60 | F20: 46120.729 | G20: 46120.771 | J20: Meal | K20: =SUMIF($B$2:$B$100000,"Meal",$E$2:$E$100000) -> 9919 | N20: Flex Time / Unavailable | O20: =K28/60 -> 0 | P20: =O20/$O$3 -> 0
A21: Amy Smiley | B21: No ticket | D21: Yes | E21: 6 | F21: 46121.412 | G21: 46121.417 | J21: Coaching | K21: =SUMIF($B$2:$B$100000,"Coaching ",$E$2:$E$100000) -> 554 | N21: Site Closure | O21: =K7/60 -> 0 | P21: =O21/$O$3 -> 0
A22: Amy Smiley | B22: On Queue | D22: Yes | E22: 45 | F22: 46121.417 | G22: 46121.448 | J22: Team Huddle | K22: =SUMIF($B$2:$B$100000,"Team Huddle",$E$2:$E$100000) -> 1363
A23: Amy Smiley | B23: Shift Abandoned | D23: No | E23: 6 | F23: 46121.448 | G23: 46121.452 | J23: Meeting | K23: =SUMIF($B$2:$B$100000,"Team Huddle",$E$2:$E$100000) -> 1363 | N23: Productive Time | O23: Unproductive Time
A24: Amy Smiley | B24: On Queue | D24: Yes | E24: 69 | F24: 46121.452 | G24: 46121.5 | J24: Peer Coaching | K24: =SUMIF($B$2:$B$100000,"Meeting",$E$2:$E$100000) -> 150 | N24: =P4+P6+P11+P12+P13+P14+P15+P16+P17 -> 0.75600165 | O24: =P5+P7+P8+P9+P10+P18+P19+P20+P21 -> 0.24399835
A25: Amy Smiley | B25: Break | D25: Yes | E25: 15 | F25: 46121.5 | G25: 46121.51 | J25: SME Support | K25: =SUMIF($B$2:$B$100000,"SME Support",$E$2:$E$100000) -> 0
A26: Amy Smiley | B26: On Queue | D26: Yes | E26: 105 | F26: 46121.51 | G26: 46121.583 | J26: Back Office | K26: =SUMIF($B$2:$B$100000,"Back Office",$E$2:$E$100000) -> 0
A27: Amy Smiley | B27: Meal | D27: No | E27: 30 | F27: 46121.583 | G27: 46121.604 | J27: Off Queue | K27: =SUMIF($B$2:$B$100000,"Off Queue",$E$2:$E$100000) -> 0
A28: Amy Smiley | B28: On Queue | D28: Yes | E28: 180 | F28: 46121.604 | G28: 46121.729 | J28: Unavailable | K28: =SUMIF($B$2:$B$100000,"Unavailable",$E$2:$E$100000) -> 0
A29: Amy Smiley | B29: End of shift | D29: No | E29: 60 | F29: 46121.729 | G29: 46121.771 | J29: Training | K29: =SUMIF($B$2:$B$100000,"Training",$E$2:$E$100000) -> 585
A30: Amy Smiley | B30: On Queue | D30: Yes | E30: 144 | F30: 46122.375 | G30: 46122.475 | J30: Client Training | K30: =SUMIF($B$2:$B$100000,"Client Training",$E$2:$E$100000) -> 14586
A31: Amy Smiley | B31: Shift Abandoned | D31: No | E31: 5 | F31: 46122.475 | G31: 46122.478 | J31: Outbound | K31: =SUMIF($B$2:$B$100000,"Outbound",$E$2:$E$100000) -> 0
A32: Amy Smiley | B32: On Queue | D32: Yes | E32: 16 | F32: 46122.478 | G32: 46122.49 | J32: Agent Customer Callback | K32: =SUMIF($B$2:$B$100000,"Agent Customer Callback",$E$2:$E$100000) -> 317
A33: Amy Smiley | B33: Meal | D33: No | E33: 30 | F33: 46122.49 | G33: 46122.51 | J33: D&G System Outage | K33: =SUMIF($B$2:$B$100000,"D&G System Outage",$E$2:$E$100000) -> 0
A34: Amy Smiley | B34: On Queue | D34: Yes | E34: 135 | F34: 46122.51 | G34: 46122.604 | J34: Agent System Issues | K34: =SUMIF($B$2:$B$100000,"Agent System Issues",$E$2:$E$100000) -> 2243
A35: Amy Smiley | B35: End of shift | D35: No | E35: 60 | F35: 46122.604 | G35: 46122.646 | J35: No ticket | K35: =SUMIF($B$2:$B$100000,"No Ticket",$E$2:$E$100000) -> 1018
A36: Amy Smiley | B36: On Queue | D36: Yes | E36: 110 | F36: 46125.375 | G36: 46125.451 | J36: Off Queue - No Ticket/Request | K36: =SUMIF($B$2:$B$100000,"Off Queue - No Ticket/Request",$E$2:$E$100000) -> 286
A37: Amy Smiley | B37: Left Early | D37: No | E37: 91 | F37: 46125.451 | G37: 46125.515
A38: Amy Smiley | B38: On Queue | D38: Yes | E38: 129 | F38: 46125.515 | G38: 46125.604
A39: Amy Smiley | B39: End of shift | D39: No | E39: 60 | F39: 46125.604 | G39: 46125.646
A40: Amy Smiley | B40: Absent | C40: called in as absent- claimed has PTO - no ticket submitted in advance . | D40: No | E40: 330 | F40: 46126.375 | G40: 46126.604
...

Sheet Eval
P1: Agent Name | Q1: Agent Email | R1: Evaluations | S1: Average Score | T1: Average Critical Score
B2: TL | C2: Associate | D2: Evaluations | E2: Average Score | F2: Average Critical Score | P2: Aaliyah Kemp | Q2: Aaliyah.Kemp@corp.spdatallc.com | R2: 2 | S2: 0.89 | T2: 0
B3: Will | C3: Amy Smiley | D3: =_xlfn.XLOOKUP(C3,P:P,R:R,0) -> 0 | E3: =_xlfn.XLOOKUP(C3,P:P,S:S,0) -> 0 | F3: =_xlfn.XLOOKUP(C3,P:P,T:T,0) -> 0 | P3: Aana Taufiq | Q3: Aana.Taufiq@corp.spdatallc.com
B4: Will | C4: Angelica Gonzalez | D4: =_xlfn.XLOOKUP(C4,P:P,R:R,0) -> 0 | E4: =_xlfn.XLOOKUP(C4,P:P,S:S,0) -> 0 | F4: =_xlfn.XLOOKUP(C4,P:P,T:T,0) -> 0 | P4: Aaron Alfaro02 | Q4: Aaron.alfaro02@movate.com
B5: Will | C5: Chanetta Gant | D5: =_xlfn.XLOOKUP(C5,P:P,R:R,0) -> 0 | E5: =_xlfn.XLOOKUP(C5,P:P,S:S,0) -> 0 | F5: =_xlfn.XLOOKUP(C5,P:P,T:T,0) -> 0 | P5: Aaron Royal | Q5: Aaron.Royal@corp.spdatallc.com
B6: Will | C6: Chasady Parker | D6: =_xlfn.XLOOKUP(C6,P:P,R:R,0) -> 0 | E6: =_xlfn.XLOOKUP(C6,P:P,S:S,0) -> 0 | F6: =_xlfn.XLOOKUP(C6,P:P,T:T,0) -> 0 | P6: Abdifitah Ahmed | Q6: Abdifitah.Ahmed@corp.spdatallc.com | R6: 2 | S6: 0.89 | T6: 0
B7: Will | C7: Christina Johnson | D7: =_xlfn.XLOOKUP(C7,P:P,R:R,0) -> 0 | E7: =_xlfn.XLOOKUP(C7,P:P,S:S,0) -> 0 | F7: =_xlfn.XLOOKUP(C7,P:P,T:T,0) -> 0 | P7: Abhiuday Pundir | Q7: Abhiuday.Pundir@corp.spdatallc.com | R7: 2 | S7: 0.91 | T7: 0
B8: Will | C8: Douglas Barnes | D8: =_xlfn.XLOOKUP(C8,P:P,R:R,0) -> 9 | E8: =_xlfn.XLOOKUP(C8,P:P,S:S,0) -> 0.9 | F8: =_xlfn.XLOOKUP(C8,P:P,T:T,0) -> 1 | P8: Abigail Ruiz | Q8: Abigail.Ruiz@movate.com
B9: Will | C9: Khadijah Young | D9: =_xlfn.XLOOKUP(C9,P:P,R:R,0) -> 5 | E9: =_xlfn.XLOOKUP(C9,P:P,S:S,0) -> 0.87 | F9: =_xlfn.XLOOKUP(C9,P:P,T:T,0) -> 1 | P9: Abinash Sritharan | Q9: Abinash.Sritharan@corp.spdatallc.com | R9: 2 | S9: 0.98 | T9: 0
B10: Will | C10: Larry Moorehead | D10: =_xlfn.XLOOKUP(C10,P:P,R:R,0) -> 5 | E10: =_xlfn.XLOOKUP(C10,P:P,S:S,0) -> 1 | F10: =_xlfn.XLOOKUP(C10,P:P,T:T,0) -> 1 | P10: Abraham.Martinez | Q10: Abraham.Martinez@movate.com | R10: 4 | S10: 1 | T10: 0
B11: Will | C11: Margaret Reddy | D11: =_xlfn.XLOOKUP(C11,P:P,R:R,0) -> 5 | E11: =_xlfn.XLOOKUP(C11,P:P,S:S,0) -> 0.9 | F11: =_xlfn.XLOOKUP(C11,P:P,T:T,0) -> 1 | P11: Adam Wilkes | Q11: Adam.Wilkes@domesticandgeneral.com
B12: Will | C12: Matthew Livingstone | D12: =_xlfn.XLOOKUP(C12,P:P,R:R,0) -> 5 | E12: =_xlfn.XLOOKUP(C12,P:P,S:S,0) -> 0.92 | F12: =_xlfn.XLOOKUP(C12,P:P,T:T,0) -> 1 | P12: Aditya Karnawat | Q12: Aditya.Karnawat@corp.spdatallc.com
B13: Will | C13: Mohamed Bayoumy | D13: =_xlfn.XLOOKUP(C13,P:P,R:R,0) -> 5 | E13: =_xlfn.XLOOKUP(C13,P:P,S:S,0) -> 0.98 | F13: =_xlfn.XLOOKUP(C13,P:P,T:T,0) -> 0.90476196 | P13: Adnan Malik | Q13: Adnan.Malik@corp.spdatallc.com
B14: Will | C14: Perry Young III | D14: =_xlfn.XLOOKUP(C14,P:P,R:R,0) -> 5 | E14: =_xlfn.XLOOKUP(C14,P:P,S:S,0) -> 0.99 | F14: =_xlfn.XLOOKUP(C14,P:P,T:T,0) -> 1 | P14: Adonis Rosalle | Q14: Adonis.Rosalle@corp.spdatallc.com
B15: Will | C15: Regina Watson | D15: =_xlfn.XLOOKUP(C15,P:P,R:R,0) -> 5 | E15: =_xlfn.XLOOKUP(C15,P:P,S:S,0) -> 1 | F15: =_xlfn.XLOOKUP(C15,P:P,T:T,0) -> 1 | P15: Adrian Marin | Q15: Adrian.Marin@movate.com
B16: Nick | C16: Carla Grant | D16: =_xlfn.XLOOKUP(C16,P:P,R:R,0) -> 0 | E16: =_xlfn.XLOOKUP(C16,P:P,S:S,0) -> 0 | F16: =_xlfn.XLOOKUP(C16,P:P,T:T,0) -> 0 | P16: Adrian Rapadas | Q16: Adrian.Rapadas@corp.spdatallc.com
B17: Nick | C17: Cassiddy Jordan | D17: =_xlfn.XLOOKUP(C17,P:P,R:R,0) -> 0 | E17: =_xlfn.XLOOKUP(C17,P:P,S:S,0) -> 0 | F17: =_xlfn.XLOOKUP(C17,P:P,T:T,0) -> 0 | P17: Adrian Underwood | Q17: Adrian.Underwood@corp.spdatallc.com
B18: Nick | C18: Christian Elizabeth | D18: =_xlfn.XLOOKUP(C18,P:P,R:R,0) -> 0 | E18: =_xlfn.XLOOKUP(C18,P:P,S:S,0) -> 0 | F18: =_xlfn.XLOOKUP(C18,P:P,T:T,0) -> 0 | P18: Adriana Alejandra Ayala Orellana | Q18: aaayala@theofficegurus.biz
B19: Nick | C19: Destiny Rich | D19: =_xlfn.XLOOKUP(C19,P:P,R:R,0) -> 6 | E19: =_xlfn.XLOOKUP(C19,P:P,S:S,0) -> 0.8 | F19: =_xlfn.XLOOKUP(C19,P:P,T:T,0) -> 1 | P19: Adriana Daniela Molina Tobares | Q19: adtobares@theofficegurus.biz | R19: 1 | S19: 0.77 | T19: 0
B20: Nick | C20: Dinesh Kandoth | D20: =_xlfn.XLOOKUP(C20,P:P,R:R,0) -> 6 | E20: =_xlfn.XLOOKUP(C20,P:P,S:S,0) -> 0.85 | F20: =_xlfn.XLOOKUP(C20,P:P,T:T,0) -> 1 | P20: Ahmed Nur | Q20: Ahmed.Nur@corp.spdatallc.com
B21: Nick | C21: Donna Plummer | D21: =_xlfn.XLOOKUP(C21,P:P,R:R,0) -> 6 | E21: =_xlfn.XLOOKUP(C21,P:P,S:S,0) -> 0.87 | F21: =_xlfn.XLOOKUP(C21,P:P,T:T,0) -> 1 | P21: Akeem Aman | Q21: Akeem.Aman@corp.spdatallc.com
B22: Nick | C22: Eric Brown | D22: =_xlfn.XLOOKUP(C22,P:P,R:R,0) -> 6 | E22: =_xlfn.XLOOKUP(C22,P:P,S:S,0) -> 0.82 | F22: =_xlfn.XLOOKUP(C22,P:P,T:T,0) -> 1 | P22: Akhil Karra | Q22: Akhil.Karra@corp.spdatallc.com | R22: 2 | S22: 0.81 | T22: 0
B23: Nick | C23: Heather Kester | D23: =_xlfn.XLOOKUP(C23,P:P,R:R,0) -> 6 | E23: =_xlfn.XLOOKUP(C23,P:P,S:S,0) -> 0.93 | F23: =_xlfn.XLOOKUP(C23,P:P,T:T,0) -> 1 | P23: Akib Lipu | Q23: Akib.Lipu@corp.spdatallc.com
B24: Nick | C24: Javier Ottenwalder | D24: =_xlfn.XLOOKUP(C24,P:P,R:R,0) -> 7 | E24: =_xlfn.XLOOKUP(C24,P:P,S:S,0) -> 0.95 | F24: =_xlfn.XLOOKUP(C24,P:P,T:T,0) -> 1 | P24: Alan Bladimir Funes Ventura | Q24: afunes@theofficegurus.biz
B25: Nick | C25: Kellee Silva | D25: =_xlfn.XLOOKUP(C25,P:P,R:R,0) -> 5 | E25: =_xlfn.XLOOKUP(C25,P:P,S:S,0) -> 0.96 | F25: =_xlfn.XLOOKUP(C25,P:P,T:T,0) -> 1 | P25: Alan Houston | Q25: Alan.Houston@domesticandgeneral.com
B26: Nick | C26: Marcia Fabry | D26: =_xlfn.XLOOKUP(C26,P:P,R:R,0) -> 5 | E26: =_xlfn.XLOOKUP(C26,P:P,S:S,0) -> 0.99 | F26: =_xlfn.XLOOKUP(C26,P:P,T:T,0) -> 1 | P26: Albany Covington-Owens | Q26: Albany.Owens@corp.spdatallc.com
B27: Nick | C27: Michael Moyer | D27: =_xlfn.XLOOKUP(C27,P:P,R:R,0) -> 5 | E27: =_xlfn.XLOOKUP(C27,P:P,S:S,0) -> 0.96 | F27: =_xlfn.XLOOKUP(C27,P:P,T:T,0) -> 1 | P27: Albert Hartinger | Q27: Albert.Hartinger@corp.spdatallc.com
B28: Nick | C28: Oyindamola Olajoye | D28: =_xlfn.XLOOKUP(C28,P:P,R:R,0) -> 5 | E28: =_xlfn.XLOOKUP(C28,P:P,S:S,0) -> 0.97 | F28: =_xlfn.XLOOKUP(C28,P:P,T:T,0) -> 1 | P28: Alberto Montoya | Q28: Alberto.Montoya@movate.com
B29: Nick | C29: Prottasha Prentice | D29: =_xlfn.XLOOKUP(C29,P:P,R:R,0) -> 5 | E29: =_xlfn.XLOOKUP(C29,P:P,S:S,0) -> 0.92 | F29: =_xlfn.XLOOKUP(C29,P:P,T:T,0) -> 1 | P29: Alberto Zeniff Montalvo Aguila | Q29: azmaguila@theofficegurus.biz
B30: Nick | C30: SHANIQUE REID | D30: =_xlfn.XLOOKUP(C30,P:P,R:R,0) -> 5 | E30: =_xlfn.XLOOKUP(C30,P:P,S:S,0) -> 0.85 | F30: =_xlfn.XLOOKUP(C30,P:P,T:T,0) -> 1 | P30: Aldrin D'Almeida | Q30: aldrin.d'almeida@domesticandgeneral.com
B31: Nick | C31: Tika Mayo | D31: =_xlfn.XLOOKUP(C31,P:P,R:R,0) -> 5 | E31: =_xlfn.XLOOKUP(C31,P:P,S:S,0) -> 0.88 | F31: =_xlfn.XLOOKUP(C31,P:P,T:T,0) -> 1 | P31: Alejandra Leticia Diaz Beltra | Q31: aldiaz@theofficegurus.biz
B32: Nick | C32: Tina Rogers | D32: =_xlfn.XLOOKUP(C32,P:P,R:R,0) -> 5 | E32: =_xlfn.XLOOKUP(C32,P:P,S:S,0) -> 0.79 | F32: =_xlfn.XLOOKUP(C32,P:P,T:T,0) -> 1 | P32: Alejandro Ernesto Cruz Barrientos | Q32: alecruz@theofficegurus.biz
B33: Nick | C33: Trevor Berry | D33: =_xlfn.XLOOKUP(C33,P:P,R:R,0) -> 5 | E33: =_xlfn.XLOOKUP(C33,P:P,S:S,0) -> 0.7 | F33: =_xlfn.XLOOKUP(C33,P:P,T:T,0) -> 1 | P33: Alessandro.Sedo | Q33: Alessandro.Sedo@movate.com
B34: Nick | C34: Uniqua Davis | D34: =_xlfn.XLOOKUP(C34,P:P,R:R,0) -> 6 | E34: =_xlfn.XLOOKUP(C34,P:P,S:S,0) -> 0.88 | F34: =_xlfn.XLOOKUP(C34,P:P,T:T,0) -> 1 | P34: Alex Clare | Q34: Alex.Clare@corp.spdatallc.com
B35: Nick | C35: Zycariah Fowler | D35: =_xlfn.XLOOKUP(C35,P:P,R:R,0) -> 0 | E35: =_xlfn.XLOOKUP(C35,P:P,S:S,0) -> 0 | F35: =_xlfn.XLOOKUP(C35,P:P,T:T,0) -> 0 | P35: Alexander Enrique Pinto Gomez | Q35: apinto@theofficegurus.biz
D36: =_xlfn.XLOOKUP(C36,P:P,R:R,0) -> 0 | E36: =_xlfn.XLOOKUP(C36,P:P,S:S,0) -> 0 | F36: =_xlfn.XLOOKUP(C36,P:P,T:T,0) -> 0 | P36: Alexander Figueroa | Q36: aafigueroa@theofficegurus.biz
D37: =_xlfn.XLOOKUP(C37,P:P,R:R,0) -> 0 | E37: =_xlfn.XLOOKUP(C37,P:P,S:S,0) -> 0 | F37: =_xlfn.XLOOKUP(C37,P:P,T:T,0) -> 0 | P37: Alexis Brown | Q37: Alexis.Brown@corp.spdatallc.com
D38: =_xlfn.XLOOKUP(C38,P:P,R:R,0) -> 0 | E38: =_xlfn.XLOOKUP(C38,P:P,S:S,0) -> 0 | F38: =_xlfn.XLOOKUP(C38,P:P,T:T,0) -> 0 | P38: Alexis Smith | Q38: Alexis.Smith@corp.spdatallc.com | R38: 2 | S38: 0.93 | T38: 0
D39: =_xlfn.XLOOKUP(C39,P:P,R:R,0) -> 0 | E39: =_xlfn.XLOOKUP(C39,P:P,S:S,0) -> 0 | F39: =_xlfn.XLOOKUP(C39,P:P,T:T,0) -> 0 | P39: Alicia Anderson | Q39: Alicia.Anderson@corp.spdatallc.com | R39: 2 | S39: 0.9 | T39: 0
D40: =_xlfn.XLOOKUP(C40,P:P,R:R,0) -> 0 | E40: =_xlfn.XLOOKUP(C40,P:P,S:S,0) -> 0 | F40: =_xlfn.XLOOKUP(C40,P:P,T:T,0) -> 0 | P40: Alicia Chase | Q40: Alicia.Chase@corp.spdatallc.com | R40: 2 | S40: 1 | T40: 0
...

Sheet ININ
P1: Interval Start | Q1: Interval End | R1: Interval Complete | S1: Filters | T1: Media Type | U1: Agent Id | V1: Agent Name | W1: Answered | X1: Handle | Y1: Avg Handle | Z1: Avg Talk | AA1: Avg Hold | AB1: Avg ACW | AC1: Held | AD1: Transferred
I2: Row Labels | J2: Sum of Handle | P2: 46068 | Q2: 46075.021 | R2: TRUE | S2: Wrap-up: ININ-WRAP-UP-TIMEOUT; Work Team: S&P Campaign - Team Danielle McMullan; Work Team: S&P Flex Trainer and SME Team; Work Team: S&P Outbound - Team Eddie Mendoza; Work Team: S&P Retention Agents - Team William Coad; Work Team: S&P Retention Service - Team Nicholas Boudreau; Work Team: S&P Service - Nesting 1; Work Team: S&P Service - Team John Burdett; Work Team: S&P Service - Team Reina Morales; Work Team: S&P Service - Team Stefano Lista; Work Team: S&P Tel Reg - Nesting ; Work Team: S&P Tel Reg - Nesting 2; Work Team: S&P Tel Reg - Team Alex Clare; Work Team: S&P Tel Reg - Team Brian Finnstrom; Work Team: S&P Tel Reg - Team Charnetta Hull; Work Team: S&P Tel Reg - Team David Densmore; Work Team: S&P Tel Reg - Team David Locke; Work Team: S&P Tel Reg - Team Jaime Collazo; Work Team: S&P Tel Reg - Team Michael Garrion; Work Team: S&P Tel Reg - Team Raul Tejada; Work Team: S&P Tel Reg - Team Terrence Toepler | T2: voice | U2: 9ea94676-2d91-4cc9-9b19-eefd38914c27 | V2: Aaliyah Kemp | X2: 2 | Y2: 1282292.5 | Z2: 1242292.5 | AB2: 40000
C3: Amy Smiley | D3: =_xlfn.XLOOKUP(C3,I:I,J:J,0) -> 0 | I3: Aaliyah Kemp | J3: 2 | P3: 46068 | Q3: 46075.021 | R3: TRUE | S3: Wrap-up: ININ-WRAP-UP-TIMEOUT; Work Team: S&P Campaign - Team Danielle McMullan; Work Team: S&P Flex Trainer and SME Team; Work Team: S&P Outbound - Team Eddie Mendoza; Work Team: S&P Retention Agents - Team William Coad; Work Team: S&P Retention Service - Team Nicholas Boudreau; Work Team: S&P Service - Nesting 1; Work Team: S&P Service - Team John Burdett; Work Team: S&P Service - Team Reina Morales; Work Team: S&P Service - Team Stefano Lista; Work Team: S&P Tel Reg - Nesting ; Work Team: S&P Tel Reg - Nesting 2; Work Team: S&P Tel Reg - Team Alex Clare; Work Team: S&P Tel Reg - Team Brian Finnstrom; Work Team: S&P Tel Reg - Team Charnetta Hull; Work Team: S&P Tel Reg - Team David Densmore; Work Team: S&P Tel Reg - Team David Locke; Work Team: S&P Tel Reg - Team Jaime Collazo; Work Team: S&P Tel Reg - Team Michael Garrion; Work Team: S&P Tel Reg - Team Raul Tejada; Work Team: S&P Tel Reg - Team Terrence Toepler | T3: voice | U3: 3d4142a0-3469-416b-9e5a-eb4a3403e480 | V3: Aana Taufiq
C4: Angelica Gonzalez | D4: =_xlfn.XLOOKUP(C4,I:I,J:J,0) -> 7 | I4: Aana Taufiq | P4: 46068 | Q4: 46075.021 | R4: TRUE | S4: Wrap-up: ININ-WRAP-UP-TIMEOUT; Work Team: S&P Campaign - Team Danielle McMullan; Work Team: S&P Flex Trainer and SME Team; Work Team: S&P Outbound - Team Eddie Mendoza; Work Team: S&P Retention Agents - Team William Coad; Work Team: S&P Retention Service - Team Nicholas Boudreau; Work Team: S&P Service - Nesting 1; Work Team: S&P Service - Team John Burdett; Work Team: S&P Service - Team Reina Morales; Work Team: S&P Service - Team Stefano Lista; Work Team: S&P Tel Reg - Nesting ; Work Team: S&P Tel Reg - Nesting 2; Work Team: S&P Tel Reg - Team Alex Clare; Work Team: S&P Tel Reg - Team Brian Finnstrom; Work Team: S&P Tel Reg - Team Charnetta Hull; Work Team: S&P Tel Reg - Team David Densmore; Work Team: S&P Tel Reg - Team David Locke; Work Team: S&P Tel Reg - Team Jaime Collazo; Work Team: S&P Tel Reg - Team Michael Garrion; Work Team: S&P Tel Reg - Team Raul Tejada; Work Team: S&P Tel Reg - Team Terrence Toepler | T4: voice | U4: ec30c194-38f5-46d9-b9af-b673ddfdbd13 | V4: Aaron Alfaro02
C5: Chanetta Gant | D5: =_xlfn.XLOOKUP(C5,I:I,J:J,0) -> 2 | I5: Aaron Alfaro02 | P5: 46068 | Q5: 46075.021 | R5: TRUE | S5: Wrap-up: ININ-WRAP-UP-TIMEOUT; Work Team: S&P Campaign - Team Danielle McMullan; Work Team: S&P Flex Trainer and SME Team; Work Team: S&P Outbound - Team Eddie Mendoza; Work Team: S&P Retention Agents - Team William Coad; Work Team: S&P Retention Service - Team Nicholas Boudreau; Work Team: S&P Service - Nesting 1; Work Team: S&P Service - Team John Burdett; Work Team: S&P Service - Team Reina Morales; Work Team: S&P Service - Team Stefano Lista; Work Team: S&P Tel Reg - Nesting ; Work Team: S&P Tel Reg - Nesting 2; Work Team: S&P Tel Reg - Team Alex Clare; Work Team: S&P Tel Reg - Team Brian Finnstrom; Work Team: S&P Tel Reg - Team Charnetta Hull; Work Team: S&P Tel Reg - Team David Densmore; Work Team: S&P Tel Reg - Team David Locke; Work Team: S&P Tel Reg - Team Jaime Collazo; Work Team: S&P Tel Reg - Team Michael Garrion; Work Team: S&P Tel Reg - Team Raul Tejada; Work Team: S&P Tel Reg - Team Terrence Toepler | T5: voice | U5: 89694374-14c1-4860-b887-f58a19b98826 | V5: Aaron Royal
C6: Chasady Parker | D6: =_xlfn.XLOOKUP(C6,I:I,J:J,0) -> 26 | I6: Aaron Royal | P6: 46068 | Q6: 46075.021 | R6: TRUE | S6: Wrap-up: ININ-WRAP-UP-TIMEOUT; Work Team: S&P Campaign - Team Danielle McMullan; Work Team: S&P Flex Trainer and SME Team; Work Team: S&P Outbound - Team Eddie Mendoza; Work Team: S&P Retention Agents - Team William Coad; Work Team: S&P Retention Service - Team Nicholas Boudreau; Work Team: S&P Service - Nesting 1; Work Team: S&P Service - Team John Burdett; Work Team: S&P Service - Team Reina Morales; Work Team: S&P Service - Team Stefano Lista; Work Team: S&P Tel Reg - Nesting ; Work Team: S&P Tel Reg - Nesting 2; Work Team: S&P Tel Reg - Team Alex Clare; Work Team: S&P Tel Reg - Team Brian Finnstrom; Work Team: S&P Tel Reg - Team Charnetta Hull; Work Team: S&P Tel Reg - Team David Densmore; Work Team: S&P Tel Reg - Team David Locke; Work Team: S&P Tel Reg - Team Jaime Collazo; Work Team: S&P Tel Reg - Team Michael Garrion; Work Team: S&P Tel Reg - Team Raul Tejada; Work Team: S&P Tel Reg - Team Terrence Toepler | T6: voice | U6: ee618fa5-023f-4d58-92be-d5af27491f2e | V6: Abdifitah Ahmed | X6: 3 | Y6: 1091701 | Z6: 1018402 | AA6: 99897 | AB6: 40000 | AC6: 1
C7: Christina Johnson | D7: =_xlfn.XLOOKUP(C7,I:I,J:J,0) -> 0 | I7: Abdifitah Ahmed | J7: 3 | P7: 46068 | Q7: 46075.021 | R7: TRUE | S7: Wrap-up: ININ-WRAP-UP-TIMEOUT; Work Team: S&P Campaign - Team Danielle McMullan; Work Team: S&P Flex Trainer and SME Team; Work Team: S&P Outbound - Team Eddie Mendoza; Work Team: S&P Retention Agents - Team William Coad; Work Team: S&P Retention Service - Team Nicholas Boudreau; Work Team: S&P Service - Nesting 1; Work Team: S&P Service - Team John Burdett; Work Team: S&P Service - Team Reina Morales; Work Team: S&P Service - Team Stefano Lista; Work Team: S&P Tel Reg - Nesting ; Work Team: S&P Tel Reg - Nesting 2; Work Team: S&P Tel Reg - Team Alex Clare; Work Team: S&P Tel Reg - Team Brian Finnstrom; Work Team: S&P Tel Reg - Team Charnetta Hull; Work Team: S&P Tel Reg - Team David Densmore; Work Team: S&P Tel Reg - Team David Locke; Work Team: S&P Tel Reg - Team Jaime Collazo; Work Team: S&P Tel Reg - Team Michael Garrion; Work Team: S&P Tel Reg - Team Raul Tejada; Work Team: S&P Tel Reg - Team Terrence Toepler | T7: voice | U7: 74fc609e-4284-4496-ba8b-67ceb642b02f | V7: Abhiuday Pundir | X7: 1 | Y7: 967440 | Z7: 927440 | AB7: 40000
C8: Douglas Barnes | D8: =_xlfn.XLOOKUP(C8,I:I,J:J,0) -> 3 | I8: Abhiuday Pundir | J8: 1 | P8: 46068 | Q8: 46075.021 | R8: TRUE | S8: Wrap-up: ININ-WRAP-UP-TIMEOUT; Work Team: S&P Campaign - Team Danielle McMullan; Work Team: S&P Flex Trainer and SME Team; Work Team: S&P Outbound - Team Eddie Mendoza; Work Team: S&P Retention Agents - Team William Coad; Work Team: S&P Retention Service - Team Nicholas Boudreau; Work Team: S&P Service - Nesting 1; Work Team: S&P Service - Team John Burdett; Work Team: S&P Service - Team Reina Morales; Work Team: S&P Service - Team Stefano Lista; Work Team: S&P Tel Reg - Nesting ; Work Team: S&P Tel Reg - Nesting 2; Work Team: S&P Tel Reg - Team Alex Clare; Work Team: S&P Tel Reg - Team Brian Finnstrom; Work Team: S&P Tel Reg - Team Charnetta Hull; Work Team: S&P Tel Reg - Team David Densmore; Work Team: S&P Tel Reg - Team David Locke; Work Team: S&P Tel Reg - Team Jaime Collazo; Work Team: S&P Tel Reg - Team Michael Garrion; Work Team: S&P Tel Reg - Team Raul Tejada; Work Team: S&P Tel Reg - Team Terrence Toepler | T8: voice | U8: 9bd45363-41ae-4078-ae56-fdd7062c4b5e | V8: Abigail Ruiz
C9: Khadijah Young | D9: =_xlfn.XLOOKUP(C9,I:I,J:J,0) -> 0 | I9: Abigail Ruiz | P9: 46068 | Q9: 46075.021 | R9: TRUE | S9: Wrap-up: ININ-WRAP-UP-TIMEOUT; Work Team: S&P Campaign - Team Danielle McMullan; Work Team: S&P Flex Trainer and SME Team; Work Team: S&P Outbound - Team Eddie Mendoza; Work Team: S&P Retention Agents - Team William Coad; Work Team: S&P Retention Service - Team Nicholas Boudreau; Work Team: S&P Service - Nesting 1; Work Team: S&P Service - Team John Burdett; Work Team: S&P Service - Team Reina Morales; Work Team: S&P Service - Team Stefano Lista; Work Team: S&P Tel Reg - Nesting ; Work Team: S&P Tel Reg - Nesting 2; Work Team: S&P Tel Reg - Team Alex Clare; Work Team: S&P Tel Reg - Team Brian Finnstrom; Work Team: S&P Tel Reg - Team Charnetta Hull; Work Team: S&P Tel Reg - Team David Densmore; Work Team: S&P Tel Reg - Team David Locke; Work Team: S&P Tel Reg - Team Jaime Collazo; Work Team: S&P Tel Reg - Team Michael Garrion; Work Team: S&P Tel Reg - Team Raul Tejada; Work Team: S&P Tel Reg - Team Terrence Toepler | T9: voice | U9: 74de28d6-b534-4a8e-ac7b-abbe441d82e1 | V9: Abinash Sritharan | X9: 2 | Y9: 1892056.5 | Z9: 1852056.5 | AB9: 40000
C10: Larry Moorehead | D10: =_xlfn.XLOOKUP(C10,I:I,J:J,0) -> 0 | I10: Abinash Sritharan | J10: 2 | P10: 46068 | Q10: 46075.021 | R10: TRUE | S10: Wrap-up: ININ-WRAP-UP-TIMEOUT; Work Team: S&P Campaign - Team Danielle McMullan; Work Team: S&P Flex Trainer and SME Team; Work Team: S&P Outbound - Team Eddie Mendoza; Work Team: S&P Retention Agents - Team William Coad; Work Team: S&P Retention Service - Team Nicholas Boudreau; Work Team: S&P Service - Nesting 1; Work Team: S&P Service - Team John Burdett; Work Team: S&P Service - Team Reina Morales; Work Team: S&P Service - Team Stefano Lista; Work Team: S&P Tel Reg - Nesting ; Work Team: S&P Tel Reg - Nesting 2; Work Team: S&P Tel Reg - Team Alex Clare; Work Team: S&P Tel Reg - Team Brian Finnstrom; Work Team: S&P Tel Reg - Team Charnetta Hull; Work Team: S&P Tel Reg - Team David Densmore; Work Team: S&P Tel Reg - Team David Locke; Work Team: S&P Tel Reg - Team Jaime Collazo; Work Team: S&P Tel Reg - Team Michael Garrion; Work Team: S&P Tel Reg - Team Raul Tejada; Work Team: S&P Tel Reg - Team Terrence Toepler | T10: voice | U10: 4300e4bd-5df1-484b-b3a2-72807dbc0928 | V10: Abraham.Martinez
C11: Margaret Reddy | D11: =_xlfn.XLOOKUP(C11,I:I,J:J,0) -> 0 | I11: Abraham.Martinez | P11: 46068 | Q11: 46075.021 | R11: TRUE | S11: Wrap-up: ININ-WRAP-UP-TIMEOUT; Work Team: S&P Campaign - Team Danielle McMullan; Work Team: S&P Flex Trainer and SME Team; Work Team: S&P Outbound - Team Eddie Mendoza; Work Team: S&P Retention Agents - Team William Coad; Work Team: S&P Retention Service - Team Nicholas Boudreau; Work Team: S&P Service - Nesting 1; Work Team: S&P Service - Team John Burdett; Work Team: S&P Service - Team Reina Morales; Work Team: S&P Service - Team Stefano Lista; Work Team: S&P Tel Reg - Nesting ; Work Team: S&P Tel Reg - Nesting 2; Work Team: S&P Tel Reg - Team Alex Clare; Work Team: S&P Tel Reg - Team Brian Finnstrom; Work Team: S&P Tel Reg - Team Charnetta Hull; Work Team: S&P Tel Reg - Team David Densmore; Work Team: S&P Tel Reg - Team David Locke; Work Team: S&P Tel Reg - Team Jaime Collazo; Work Team: S&P Tel Reg - Team Michael Garrion; Work Team: S&P Tel Reg - Team Raul Tejada; Work Team: S&P Tel Reg - Team Terrence Toepler | T11: voice | U11: 5af13963-6e81-4b9e-bc2f-cff5a110996b | V11: Adam Wilkes
C12: Matthew Livingstone | D12: =_xlfn.XLOOKUP(C12,I:I,J:J,0) -> 1 | I12: Adam Wilkes | P12: 46068 | Q12: 46075.021 | R12: TRUE | S12: Wrap-up: ININ-WRAP-UP-TIMEOUT; Work Team: S&P Campaign - Team Danielle McMullan; Work Team: S&P Flex Trainer and SME Team; Work Team: S&P Outbound - Team Eddie Mendoza; Work Team: S&P Retention Agents - Team William Coad; Work Team: S&P Retention Service - Team Nicholas Boudreau; Work Team: S&P Service - Nesting 1; Work Team: S&P Service - Team John Burdett; Work Team: S&P Service - Team Reina Morales; Work Team: S&P Service - Team Stefano Lista; Work Team: S&P Tel Reg - Nesting ; Work Team: S&P Tel Reg - Nesting 2; Work Team: S&P Tel Reg - Team Alex Clare; Work Team: S&P Tel Reg - Team Brian Finnstrom; Work Team: S&P Tel Reg - Team Charnetta Hull; Work Team: S&P Tel Reg - Team David Densmore; Work Team: S&P Tel Reg - Team David Locke; Work Team: S&P Tel Reg - Team Jaime Collazo; Work Team: S&P Tel Reg - Team Michael Garrion; Work Team: S&P Tel Reg - Team Raul Tejada; Work Team: S&P Tel Reg - Team Terrence Toepler | T12: voice | U12: 08c10b33-30a7-4986-8ed6-efffe260db83 | V12: Aditya Karnawat
C13: Mohamed Bayoumy | D13: =_xlfn.XLOOKUP(C13,I:I,J:J,0) -> 5 | I13: Aditya Karnawat | P13: 46068 | Q13: 46075.021 | R13: TRUE | S13: Wrap-up: ININ-WRAP-UP-TIMEOUT; Work Team: S&P Campaign - Team Danielle McMullan; Work Team: S&P Flex Trainer and SME Team; Work Team: S&P Outbound - Team Eddie Mendoza; Work Team: S&P Retention Agents - Team William Coad; Work Team: S&P Retention Service - Team Nicholas Boudreau; Work Team: S&P Service - Nesting 1; Work Team: S&P Service - Team John Burdett; Work Team: S&P Service - Team Reina Morales; Work Team: S&P Service - Team Stefano Lista; Work Team: S&P Tel Reg - Nesting ; Work Team: S&P Tel Reg - Nesting 2; Work Team: S&P Tel Reg - Team Alex Clare; Work Team: S&P Tel Reg - Team Brian Finnstrom; Work Team: S&P Tel Reg - Team Charnetta Hull; Work Team: S&P Tel Reg - Team David Densmore; Work Team: S&P Tel Reg - Team David Locke; Work Team: S&P Tel Reg - Team Jaime Collazo; Work Team: S&P Tel Reg - Team Michael Garrion; Work Team: S&P Tel Reg - Team Raul Tejada; Work Team: S&P Tel Reg - Team Terrence Toepler | T13: voice | U13: 745d5421-d7e5-404f-b96f-c0188fb35fef | V13: Adnan Malik | X13: 3 | Y13: 372832.67 | Z13: 282039.33 | AA13: 146955 | AB13: 40000 | AC13: 1
C14: Perry Young III | D14: =_xlfn.XLOOKUP(C14,I:I,J:J,0) -> 3 | I14: Adnan Malik | J14: 3 | P14: 46068 | Q14: 46075.021 | R14: TRUE | S14: Wrap-up: ININ-WRAP-UP-TIMEOUT; Work Team: S&P Campaign - Team Danielle McMullan; Work Team: S&P Flex Trainer and SME Team; Work Team: S&P Outbound - Team Eddie Mendoza; Work Team: S&P Retention Agents - Team William Coad; Work Team: S&P Retention Service - Team Nicholas Boudreau; Work Team: S&P Service - Nesting 1; Work Team: S&P Service - Team John Burdett; Work Team: S&P Service - Team Reina Morales; Work Team: S&P Service - Team Stefano Lista; Work Team: S&P Tel Reg - Nesting ; Work Team: S&P Tel Reg - Nesting 2; Work Team: S&P Tel Reg - Team Alex Clare; Work Team: S&P Tel Reg - Team Brian Finnstrom; Work Team: S&P Tel Reg - Team Charnetta Hull; Work Team: S&P Tel Reg - Team David Densmore; Work Team: S&P Tel Reg - Team David Locke; Work Team: S&P Tel Reg - Team Jaime Collazo; Work Team: S&P Tel Reg - Team Michael Garrion; Work Team: S&P Tel Reg - Team Raul Tejada; Work Team: S&P Tel Reg - Team Terrence Toepler | T14: voice | U14: a584ef3e-fed4-47ae-87db-899690f9434a | V14: Adonis Rosalle
C15: Regina Watson | D15: =_xlfn.XLOOKUP(C15,I:I,J:J,0) -> 5 | I15: Adonis Rosalle | P15: 46068 | Q15: 46075.021 | R15: TRUE | S15: Wrap-up: ININ-WRAP-UP-TIMEOUT; Work Team: S&P Campaign - Team Danielle McMullan; Work Team: S&P Flex Trainer and SME Team; Work Team: S&P Outbound - Team Eddie Mendoza; Work Team: S&P Retention Agents - Team William Coad; Work Team: S&P Retention Service - Team Nicholas Boudreau; Work Team: S&P Service - Nesting 1; Work Team: S&P Service - Team John Burdett; Work Team: S&P Service - Team Reina Morales; Work Team: S&P Service - Team Stefano Lista; Work Team: S&P Tel Reg - Nesting ; Work Team: S&P Tel Reg - Nesting 2; Work Team: S&P Tel Reg - Team Alex Clare; Work Team: S&P Tel Reg - Team Brian Finnstrom; Work Team: S&P Tel Reg - Team Charnetta Hull; Work Team: S&P Tel Reg - Team David Densmore; Work Team: S&P Tel Reg - Team David Locke; Work Team: S&P Tel Reg - Team Jaime Collazo; Work Team: S&P Tel Reg - Team Michael Garrion; Work Team: S&P Tel Reg - Team Raul Tejada; Work Team: S&P Tel Reg - Team Terrence Toepler | T15: voice | U15: 5cd9227a-47f1-40a5-867c-f0b59d01b4d7 | V15: Adrian Marin
C16: Carla Grant | D16: =_xlfn.XLOOKUP(C16,I:I,J:J,0) -> 21 | I16: Adrian Marin | P16: 46068 | Q16: 46075.021 | R16: TRUE | S16: Wrap-up: ININ-WRAP-UP-TIMEOUT; Work Team: S&P Campaign - Team Danielle McMullan; Work Team: S&P Flex Trainer and SME Team; Work Team: S&P Outbound - Team Eddie Mendoza; Work Team: S&P Retention Agents - Team William Coad; Work Team: S&P Retention Service - Team Nicholas Boudreau; Work Team: S&P Service - Nesting 1; Work Team: S&P Service - Team John Burdett; Work Team: S&P Service - Team Reina Morales; Work Team: S&P Service - Team Stefano Lista; Work Team: S&P Tel Reg - Nesting ; Work Team: S&P Tel Reg - Nesting 2; Work Team: S&P Tel Reg - Team Alex Clare; Work Team: S&P Tel Reg - Team Brian Finnstrom; Work Team: S&P Tel Reg - Team Charnetta Hull; Work Team: S&P Tel Reg - Team David Densmore; Work Team: S&P Tel Reg - Team David Locke; Work Team: S&P Tel Reg - Team Jaime Collazo; Work Team: S&P Tel Reg - Team Michael Garrion; Work Team: S&P Tel Reg - Team Raul Tejada; Work Team: S&P Tel Reg - Team Terrence Toepler | T16: voice | U16: 53eb2405-d5d2-46cb-8f43-2fa1efe404f3 | V16: Adrian Rapadas
C17: Cassiddy Jordan | D17: =_xlfn.XLOOKUP(C17,I:I,J:J,0) -> 2 | I17: Adrian Rapadas | P17: 46068 | Q17: 46075.021 | R17: TRUE | S17: Wrap-up: ININ-WRAP-UP-TIMEOUT; Work Team: S&P Campaign - Team Danielle McMullan; Work Team: S&P Flex Trainer and SME Team; Work Team: S&P Outbound - Team Eddie Mendoza; Work Team: S&P Retention Agents - Team William Coad; Work Team: S&P Retention Service - Team Nicholas Boudreau; Work Team: S&P Service - Nesting 1; Work Team: S&P Service - Team John Burdett; Work Team: S&P Service - Team Reina Morales; Work Team: S&P Service - Team Stefano Lista; Work Team: S&P Tel Reg - Nesting ; Work Team: S&P Tel Reg - Nesting 2; Work Team: S&P Tel Reg - Team Alex Clare; Work Team: S&P Tel Reg - Team Brian Finnstrom; Work Team: S&P Tel Reg - Team Charnetta Hull; Work Team: S&P Tel Reg - Team David Densmore; Work Team: S&P Tel Reg - Team David Locke; Work Team: S&P Tel Reg - Team Jaime Collazo; Work Team: S&P Tel Reg - Team Michael Garrion; Work Team: S&P Tel Reg - Team Raul Tejada; Work Team: S&P Tel Reg - Team Terrence Toepler | T17: voice | U17: 463ad4f9-1e92-4e8e-adf7-c88c16f8cc0f | V17: Adrian Underwood
C18: Christian Elizabeth | D18: =_xlfn.XLOOKUP(C18,I:I,J:J,0) -> 0 | I18: Adrian Underwood | P18: 46068 | Q18: 46075.021 | R18: TRUE | S18: Wrap-up: ININ-WRAP-UP-TIMEOUT; Work Team: S&P Campaign - Team Danielle McMullan; Work Team: S&P Flex Trainer and SME Team; Work Team: S&P Outbound - Team Eddie Mendoza; Work Team: S&P Retention Agents - Team William Coad; Work Team: S&P Retention Service - Team Nicholas Boudreau; Work Team: S&P Service - Nesting 1; Work Team: S&P Service - Team John Burdett; Work Team: S&P Service - Team Reina Morales; Work Team: S&P Service - Team Stefano Lista; Work Team: S&P Tel Reg - Nesting ; Work Team: S&P Tel Reg - Nesting 2; Work Team: S&P Tel Reg - Team Alex Clare; Work Team: S&P Tel Reg - Team Brian Finnstrom; Work Team: S&P Tel Reg - Team Charnetta Hull; Work Team: S&P Tel Reg - Team David Densmore; Work Team: S&P Tel Reg - Team David Locke; Work Team: S&P Tel Reg - Team Jaime Collazo; Work Team: S&P Tel Reg - Team Michael Garrion; Work Team: S&P Tel Reg - Team Raul Tejada; Work Team: S&P Tel Reg - Team Terrence Toepler | T18: voice | U18: 9231ba2d-f7c6-4c2d-ac20-68553371bcca | V18: Adriana Alejandra Ayala Orellana
C19: Destiny Rich | D19: =_xlfn.XLOOKUP(C19,I:I,J:J,0) -> 22 | I19: Adriana Alejandra Ayala Orellana | P19: 46068 | Q19: 46075.021 | R19: TRUE | S19: Wrap-up: ININ-WRAP-UP-TIMEOUT; Work Team: S&P Campaign - Team Danielle McMullan; Work Team: S&P Flex Trainer and SME Team; Work Team: S&P Outbound - Team Eddie Mendoza; Work Team: S&P Retention Agents - Team William Coad; Work Team: S&P Retention Service - Team Nicholas Boudreau; Work Team: S&P Service - Nesting 1; Work Team: S&P Service - Team John Burdett; Work Team: S&P Service - Team Reina Morales; Work Team: S&P Service - Team Stefano Lista; Work Team: S&P Tel Reg - Nesting ; Work Team: S&P Tel Reg - Nesting 2; Work Team: S&P Tel Reg - Team Alex Clare; Work Team: S&P Tel Reg - Team Brian Finnstrom; Work Team: S&P Tel Reg - Team Charnetta Hull; Work Team: S&P Tel Reg - Team David Densmore; Work Team: S&P Tel Reg - Team David Locke; Work Team: S&P Tel Reg - Team Jaime Collazo; Work Team: S&P Tel Reg - Team Michael Garrion; Work Team: S&P Tel Reg - Team Raul Tejada; Work Team: S&P Tel Reg - Team Terrence Toepler | T19: voice | U19: 93f8db7a-f512-4e9b-b85f-bd166d794d44 | V19: Adriana Daniela Molina Tobares
C20: Dinesh Kandoth | D20: =_xlfn.XLOOKUP(C20,I:I,J:J,0) -> 1 | I20: Adriana Daniela Molina Tobares | P20: 46068 | Q20: 46075.021 | R20: TRUE | S20: Wrap-up: ININ-WRAP-UP-TIMEOUT; Work Team: S&P Campaign - Team Danielle McMullan; Work Team: S&P Flex Trainer and SME Team; Work Team: S&P Outbound - Team Eddie Mendoza; Work Team: S&P Retention Agents - Team William Coad; Work Team: S&P Retention Service - Team Nicholas Boudreau; Work Team: S&P Service - Nesting 1; Work Team: S&P Service - Team John Burdett; Work Team: S&P Service - Team Reina Morales; Work Team: S&P Service - Team Stefano Lista; Work Team: S&P Tel Reg - Nesting ; Work Team: S&P Tel Reg - Nesting 2; Work Team: S&P Tel Reg - Team Alex Clare; Work Team: S&P Tel Reg - Team Brian Finnstrom; Work Team: S&P Tel Reg - Team Charnetta Hull; Work Team: S&P Tel Reg - Team David Densmore; Work Team: S&P Tel Reg - Team David Locke; Work Team: S&P Tel Reg - Team Jaime Collazo; Work Team: S&P Tel Reg - Team Michael Garrion; Work Team: S&P Tel Reg - Team Raul Tejada; Work Team: S&P Tel Reg - Team Terrence Toepler | T20: voice | U20: f602411e-342d-4b63-ad96-393eaaf8fe71 | V20: Ahmed Nur
C21: Donna Plummer | D21: =_xlfn.XLOOKUP(C21,I:I,J:J,0) -> 10 | I21: Ahmed Nur | P21: 46068 | Q21: 46075.021 | R21: TRUE | S21: Wrap-up: ININ-WRAP-UP-TIMEOUT; Work Team: S&P Campaign - Team Danielle McMullan; Work Team: S&P Flex Trainer and SME Team; Work Team: S&P Outbound - Team Eddie Mendoza; Work Team: S&P Retention Agents - Team William Coad; Work Team: S&P Retention Service - Team Nicholas Boudreau; Work Team: S&P Service - Nesting 1; Work Team: S&P Service - Team John Burdett; Work Team: S&P Service - Team Reina Morales; Work Team: S&P Service - Team Stefano Lista; Work Team: S&P Tel Reg - Nesting ; Work Team: S&P Tel Reg - Nesting 2; Work Team: S&P Tel Reg - Team Alex Clare; Work Team: S&P Tel Reg - Team Brian Finnstrom; Work Team: S&P Tel Reg - Team Charnetta Hull; Work Team: S&P Tel Reg - Team David Densmore; Work Team: S&P Tel Reg - Team David Locke; Work Team: S&P Tel Reg - Team Jaime Collazo; Work Team: S&P Tel Reg - Team Michael Garrion; Work Team: S&P Tel Reg - Team Raul Tejada; Work Team: S&P Tel Reg - Team Terrence Toepler | T21: voice | U21: 05e01ca3-b798-447a-9e05-663ac746cdb5 | V21: Akeem Aman
C22: Eric Brown | D22: =_xlfn.XLOOKUP(C22,I:I,J:J,0) -> 13 | I22: Akeem Aman | P22: 46068 | Q22: 46075.021 | R22: TRUE | S22: Wrap-up: ININ-WRAP-UP-TIMEOUT; Work Team: S&P Campaign - Team Danielle McMullan; Work Team: S&P Flex Trainer and SME Team; Work Team: S&P Outbound - Team Eddie Mendoza; Work Team: S&P Retention Agents - Team William Coad; Work Team: S&P Retention Service - Team Nicholas Boudreau; Work Team: S&P Service - Nesting 1; Work Team: S&P Service - Team John Burdett; Work Team: S&P Service - Team Reina Morales; Work Team: S&P Service - Team Stefano Lista; Work Team: S&P Tel Reg - Nesting ; Work Team: S&P Tel Reg - Nesting 2; Work Team: S&P Tel Reg - Team Alex Clare; Work Team: S&P Tel Reg - Team Brian Finnstrom; Work Team: S&P Tel Reg - Team Charnetta Hull; Work Team: S&P Tel Reg - Team David Densmore; Work Team: S&P Tel Reg - Team David Locke; Work Team: S&P Tel Reg - Team Jaime Collazo; Work Team: S&P Tel Reg - Team Michael Garrion; Work Team: S&P Tel Reg - Team Raul Tejada; Work Team: S&P Tel Reg - Team Terrence Toepler | T22: voice | U22: 27cc6d0a-1f8c-4d53-bb13-871b35ec1aa7 | V22: Akhil Karra | X22: 2 | Y22: 410940.5 | Z22: 370940.5 | AB22: 40000
C23: Heather Kester | D23: =_xlfn.XLOOKUP(C23,I:I,J:J,0) -> 21 | I23: Akhil Karra | J23: 2 | P23: 46068 | Q23: 46075.021 | R23: TRUE | S23: Wrap-up: ININ-WRAP-UP-TIMEOUT; Work Team: S&P Campaign - Team Danielle McMullan; Work Team: S&P Flex Trainer and SME Team; Work Team: S&P Outbound - Team Eddie Mendoza; Work Team: S&P Retention Agents - Team William Coad; Work Team: S&P Retention Service - Team Nicholas Boudreau; Work Team: S&P Service - Nesting 1; Work Team: S&P Service - Team John Burdett; Work Team: S&P Service - Team Reina Morales; Work Team: S&P Service - Team Stefano Lista; Work Team: S&P Tel Reg - Nesting ; Work Team: S&P Tel Reg - Nesting 2; Work Team: S&P Tel Reg - Team Alex Clare; Work Team: S&P Tel Reg - Team Brian Finnstrom; Work Team: S&P Tel Reg - Team Charnetta Hull; Work Team: S&P Tel Reg - Team David Densmore; Work Team: S&P Tel Reg - Team David Locke; Work Team: S&P Tel Reg - Team Jaime Collazo; Work Team: S&P Tel Reg - Team Michael Garrion; Work Team: S&P Tel Reg - Team Raul Tejada; Work Team: S&P Tel Reg - Team Terrence Toepler | T23: voice | U23: f304c468-a023-4d32-ab8c-7271adf9a391 | V23: Akib Lipu
C24: Javier Ottenwalder | D24: =_xlfn.XLOOKUP(C24,I:I,J:J,0) -> 9 | I24: Akib Lipu | P24: 46068 | Q24: 46075.021 | R24: TRUE | S24: Wrap-up: ININ-WRAP-UP-TIMEOUT; Work Team: S&P Campaign - Team Danielle McMullan; Work Team: S&P Flex Trainer and SME Team; Work Team: S&P Outbound - Team Eddie Mendoza; Work Team: S&P Retention Agents - Team William Coad; Work Team: S&P Retention Service - Team Nicholas Boudreau; Work Team: S&P Service - Nesting 1; Work Team: S&P Service - Team John Burdett; Work Team: S&P Service - Team Reina Morales; Work Team: S&P Service - Team Stefano Lista; Work Team: S&P Tel Reg - Nesting ; Work Team: S&P Tel Reg - Nesting 2; Work Team: S&P Tel Reg - Team Alex Clare; Work Team: S&P Tel Reg - Team Brian Finnstrom; Work Team: S&P Tel Reg - Team Charnetta Hull; Work Team: S&P Tel Reg - Team David Densmore; Work Team: S&P Tel Reg - Team David Locke; Work Team: S&P Tel Reg - Team Jaime Collazo; Work Team: S&P Tel Reg - Team Michael Garrion; Work Team: S&P Tel Reg - Team Raul Tejada; Work Team: S&P Tel Reg - Team Terrence Toepler | T24: voice | U24: dafaef3a-8e0d-471c-9c79-e060a7ab3022 | V24: Alan Bladimir Funes Ventura
C25: Kellee Silva | D25: =_xlfn.XLOOKUP(C25,I:I,J:J,0) -> 14 | I25: Alan Bladimir Funes Ventura | P25: 46068 | Q25: 46075.021 | R25: TRUE | S25: Wrap-up: ININ-WRAP-UP-TIMEOUT; Work Team: S&P Campaign - Team Danielle McMullan; Work Team: S&P Flex Trainer and SME Team; Work Team: S&P Outbound - Team Eddie Mendoza; Work Team: S&P Retention Agents - Team William Coad; Work Team: S&P Retention Service - Team Nicholas Boudreau; Work Team: S&P Service - Nesting 1; Work Team: S&P Service - Team John Burdett; Work Team: S&P Service - Team Reina Morales; Work Team: S&P Service - Team Stefano Lista; Work Team: S&P Tel Reg - Nesting ; Work Team: S&P Tel Reg - Nesting 2; Work Team: S&P Tel Reg - Team Alex Clare; Work Team: S&P Tel Reg - Team Brian Finnstrom; Work Team: S&P Tel Reg - Team Charnetta Hull; Work Team: S&P Tel Reg - Team David Densmore; Work Team: S&P Tel Reg - Team David Locke; Work Team: S&P Tel Reg - Team Jaime Collazo; Work Team: S&P Tel Reg - Team Michael Garrion; Work Team: S&P Tel Reg - Team Raul Tejada; Work Team: S&P Tel Reg - Team Terrence Toepler | T25: voice | U25: 362e8490-673f-4698-a9c5-3035faaca765 | V25: Alan Houston
C26: Marcia Fabry | D26: =_xlfn.XLOOKUP(C26,I:I,J:J,0) -> 10 | I26: Alan Houston | P26: 46068 | Q26: 46075.021 | R26: TRUE | S26: Wrap-up: ININ-WRAP-UP-TIMEOUT; Work Team: S&P Campaign - Team Danielle McMullan; Work Team: S&P Flex Trainer and SME Team; Work Team: S&P Outbound - Team Eddie Mendoza; Work Team: S&P Retention Agents - Team William Coad; Work Team: S&P Retention Service - Team Nicholas Boudreau; Work Team: S&P Service - Nesting 1; Work Team: S&P Service - Team John Burdett; Work Team: S&P Service - Team Reina Morales; Work Team: S&P Service - Team Stefano Lista; Work Team: S&P Tel Reg - Nesting ; Work Team: S&P Tel Reg - Nesting 2; Work Team: S&P Tel Reg - Team Alex Clare; Work Team: S&P Tel Reg - Team Brian Finnstrom; Work Team: S&P Tel Reg - Team Charnetta Hull; Work Team: S&P Tel Reg - Team David Densmore; Work Team: S&P Tel Reg - Team David Locke; Work Team: S&P Tel Reg - Team Jaime Collazo; Work Team: S&P Tel Reg - Team Michael Garrion; Work Team: S&P Tel Reg - Team Raul Tejada; Work Team: S&P Tel Reg - Team Terrence Toepler | T26: voice | U26: c0f67450-ff61-4dd6-8eec-0e6b2aa5502d | V26: Albany Covington-Owens
C27: Michael Moyer | D27: =_xlfn.XLOOKUP(C27,I:I,J:J,0) -> 25 | I27: Albany Covington-Owens | P27: 46068 | Q27: 46075.021 | R27: TRUE | S27: Wrap-up: ININ-WRAP-UP-TIMEOUT; Work Team: S&P Campaign - Team Danielle McMullan; Work Team: S&P Flex Trainer and SME Team; Work Team: S&P Outbound - Team Eddie Mendoza; Work Team: S&P Retention Agents - Team William Coad; Work Team: S&P Retention Service - Team Nicholas Boudreau; Work Team: S&P Service - Nesting 1; Work Team: S&P Service - Team John Burdett; Work Team: S&P Service - Team Reina Morales; Work Team: S&P Service - Team Stefano Lista; Work Team: S&P Tel Reg - Nesting ; Work Team: S&P Tel Reg - Nesting 2; Work Team: S&P Tel Reg - Team Alex Clare; Work Team: S&P Tel Reg - Team Brian Finnstrom; Work Team: S&P Tel Reg - Team Charnetta Hull; Work Team: S&P Tel Reg - Team David Densmore; Work Team: S&P Tel Reg - Team David Locke; Work Team: S&P Tel Reg - Team Jaime Collazo; Work Team: S&P Tel Reg - Team Michael Garrion; Work Team: S&P Tel Reg - Team Raul Tejada; Work Team: S&P Tel Reg - Team Terrence Toepler | T27: voice | U27: b141ab5d-43de-4f61-b229-3e55e5569501 | V27: Albert Hartinger
C28: Oyindamola Olajoye | D28: =_xlfn.XLOOKUP(C28,I:I,J:J,0) -> 0 | I28: Albert Hartinger | P28: 46068 | Q28: 46075.021 | R28: TRUE | S28: Wrap-up: ININ-WRAP-UP-TIMEOUT; Work Team: S&P Campaign - Team Danielle McMullan; Work Team: S&P Flex Trainer and SME Team; Work Team: S&P Outbound - Team Eddie Mendoza; Work Team: S&P Retention Agents - Team William Coad; Work Team: S&P Retention Service - Team Nicholas Boudreau; Work Team: S&P Service - Nesting 1; Work Team: S&P Service - Team John Burdett; Work Team: S&P Service - Team Reina Morales; Work Team: S&P Service - Team Stefano Lista; Work Team: S&P Tel Reg - Nesting ; Work Team: S&P Tel Reg - Nesting 2; Work Team: S&P Tel Reg - Team Alex Clare; Work Team: S&P Tel Reg - Team Brian Finnstrom; Work Team: S&P Tel Reg - Team Charnetta Hull; Work Team: S&P Tel Reg - Team David Densmore; Work Team: S&P Tel Reg - Team David Locke; Work Team: S&P Tel Reg - Team Jaime Collazo; Work Team: S&P Tel Reg - Team Michael Garrion; Work Team: S&P Tel Reg - Team Raul Tejada; Work Team: S&P Tel Reg - Team Terrence Toepler | T28: voice | U28: 2de27936-339a-437b-9aa2-b145a7cb5a4d | V28: Alberto Montoya
C29: Prottasha Prentice | D29: =_xlfn.XLOOKUP(C29,I:I,J:J,0) -> 13 | I29: Alberto Montoya | P29: 46068 | Q29: 46075.021 | R29: TRUE | S29: Wrap-up: ININ-WRAP-UP-TIMEOUT; Work Team: S&P Campaign - Team Danielle McMullan; Work Team: S&P Flex Trainer and SME Team; Work Team: S&P Outbound - Team Eddie Mendoza; Work Team: S&P Retention Agents - Team William Coad; Work Team: S&P Retention Service - Team Nicholas Boudreau; Work Team: S&P Service - Nesting 1; Work Team: S&P Service - Team John Burdett; Work Team: S&P Service - Team Reina Morales; Work Team: S&P Service - Team Stefano Lista; Work Team: S&P Tel Reg - Nesting ; Work Team: S&P Tel Reg - Nesting 2; Work Team: S&P Tel Reg - Team Alex Clare; Work Team: S&P Tel Reg - Team Brian Finnstrom; Work Team: S&P Tel Reg - Team Charnetta Hull; Work Team: S&P Tel Reg - Team David Densmore; Work Team: S&P Tel Reg - Team David Locke; Work Team: S&P Tel Reg - Team Jaime Collazo; Work Team: S&P Tel Reg - Team Michael Garrion; Work Team: S&P Tel Reg - Team Raul Tejada; Work Team: S&P Tel Reg - Team Terrence Toepler | T29: voice | U29: 6146d8cf-ce51-49c3-b46e-f3cc3aad31eb | V29: Alberto Zeniff Montalvo Aguila
C30: SHANIQUE REID | D30: =_xlfn.XLOOKUP(C30,I:I,J:J,0) -> 21 | I30: Alberto Zeniff Montalvo Aguila | P30: 46068 | Q30: 46075.021 | R30: TRUE | S30: Wrap-up: ININ-WRAP-UP-TIMEOUT; Work Team: S&P Campaign - Team Danielle McMullan; Work Team: S&P Flex Trainer and SME Team; Work Team: S&P Outbound - Team Eddie Mendoza; Work Team: S&P Retention Agents - Team William Coad; Work Team: S&P Retention Service - Team Nicholas Boudreau; Work Team: S&P Service - Nesting 1; Work Team: S&P Service - Team John Burdett; Work Team: S&P Service - Team Reina Morales; Work Team: S&P Service - Team Stefano Lista; Work Team: S&P Tel Reg - Nesting ; Work Team: S&P Tel Reg - Nesting 2; Work Team: S&P Tel Reg - Team Alex Clare; Work Team: S&P Tel Reg - Team Brian Finnstrom; Work Team: S&P Tel Reg - Team Charnetta Hull; Work Team: S&P Tel Reg - Team David Densmore; Work Team: S&P Tel Reg - Team David Locke; Work Team: S&P Tel Reg - Team Jaime Collazo; Work Team: S&P Tel Reg - Team Michael Garrion; Work Team: S&P Tel Reg - Team Raul Tejada; Work Team: S&P Tel Reg - Team Terrence Toepler | T30: voice | U30: 15122abc-b966-488d-af5d-312aa43a7cdc | V30: Aldrin D'Almeida
C31: Tika Mayo | D31: =_xlfn.XLOOKUP(C31,I:I,J:J,0) -> 26 | I31: Aldrin D'Almeida | P31: 46068 | Q31: 46075.021 | R31: TRUE | S31: Wrap-up: ININ-WRAP-UP-TIMEOUT; Work Team: S&P Campaign - Team Danielle McMullan; Work Team: S&P Flex Trainer and SME Team; Work Team: S&P Outbound - Team Eddie Mendoza; Work Team: S&P Retention Agents - Team William Coad; Work Team: S&P Retention Service - Team Nicholas Boudreau; Work Team: S&P Service - Nesting 1; Work Team: S&P Service - Team John Burdett; Work Team: S&P Service - Team Reina Morales; Work Team: S&P Service - Team Stefano Lista; Work Team: S&P Tel Reg - Nesting ; Work Team: S&P Tel Reg - Nesting 2; Work Team: S&P Tel Reg - Team Alex Clare; Work Team: S&P Tel Reg - Team Brian Finnstrom; Work Team: S&P Tel Reg - Team Charnetta Hull; Work Team: S&P Tel Reg - Team David Densmore; Work Team: S&P Tel Reg - Team David Locke; Work Team: S&P Tel Reg - Team Jaime Collazo; Work Team: S&P Tel Reg - Team Michael Garrion; Work Team: S&P Tel Reg - Team Raul Tejada; Work Team: S&P Tel Reg - Team Terrence Toepler | T31: voice | U31: 7e9bf2e2-2009-4bb3-a784-164ca04e7b1e | V31: Alejandra Leticia Diaz Beltra
C32: Tina Rogers | D32: =_xlfn.XLOOKUP(C32,I:I,J:J,0) -> 44 | I32: Alejandra Leticia Diaz Beltra | P32: 46068 | Q32: 46075.021 | R32: TRUE | S32: Wrap-up: ININ-WRAP-UP-TIMEOUT; Work Team: S&P Campaign - Team Danielle McMullan; Work Team: S&P Flex Trainer and SME Team; Work Team: S&P Outbound - Team Eddie Mendoza; Work Team: S&P Retention Agents - Team William Coad; Work Team: S&P Retention Service - Team Nicholas Boudreau; Work Team: S&P Service - Nesting 1; Work Team: S&P Service - Team John Burdett; Work Team: S&P Service - Team Reina Morales; Work Team: S&P Service - Team Stefano Lista; Work Team: S&P Tel Reg - Nesting ; Work Team: S&P Tel Reg - Nesting 2; Work Team: S&P Tel Reg - Team Alex Clare; Work Team: S&P Tel Reg - Team Brian Finnstrom; Work Team: S&P Tel Reg - Team Charnetta Hull; Work Team: S&P Tel Reg - Team David Densmore; Work Team: S&P Tel Reg - Team David Locke; Work Team: S&P Tel Reg - Team Jaime Collazo; Work Team: S&P Tel Reg - Team Michael Garrion; Work Team: S&P Tel Reg - Team Raul Tejada; Work Team: S&P Tel Reg - Team Terrence Toepler | T32: voice | U32: 05004194-0d4b-4207-ad6e-65393395b5f6 | V32: Alejandro Ernesto Cruz Barrientos
