Workbook

Sheet DashBoard
E1: MTD by Tie Assoc | J1: Cases Open | U1: Cases Closed
A2: Word Days | B2: 23 | E2: Tie Associate | F2: Cases Owned | G2: Case Closed | H2: Sales | J2: Count of Account Name | K2: Column Labels | T2: Count of Status | U2: Column Labels
A3: Days Worked | B3: 17 | E3: Alyssa Torres | F3: =COUNTIF('Open SF cases MTD'!A:A,DashBoard!E3) -> 2 | G3: =_xlfn.XLOOKUP(E3,'Closed SF Cases MTD'!K:K,'Closed SF Cases MTD'!Z:Z,0) -> 2 | H3: =_xlfn.XLOOKUP(E3,BI!C:C,BI!M:M,0) -> 0 | J3: Row Labels | K3: In Process | L3: In Progress | M3: In Review | N3: New | O3: New Complaint | P3: On Hold | Q3: (blank) | R3: Grand Total | T3: Row Labels | U3: Account Support | V3: Billing | W3: Cancel Plan | X3: Email Third Party Escalations | Y3: Out of Network Repair | Z3: Parts | AA3: Plan Support | AB3: Repair Authorization | AC3: Replacement | AD3: Retention | AE3: Service Request | AF3: SR Mapping Research | AG3: Web/Portal Support | AH3: (blank) | AI3: Grand Total
A4: Cases closed P/d | B4: 8 | E4: Christina J Harris | F4: =COUNTIF('Open SF cases MTD'!A:A,DashBoard!E4) -> 22 | G4: =_xlfn.XLOOKUP(E4,'Closed SF Cases MTD'!K:K,'Closed SF Cases MTD'!Z:Z,0) -> 250 | H4: =_xlfn.XLOOKUP(E4,BI!C:C,BI!M:M,0) -> 0 | J4: Admin Tasks | N4: 26 | R4: 26 | T4: Admin Tasks | AA4: 1 | AH4: 1715 | AI4: 1716
E5: Clarene Stapleton | F5: =COUNTIF('Open SF cases MTD'!A:A,DashBoard!E5) -> 40 | G5: =_xlfn.XLOOKUP(E5,'Closed SF Cases MTD'!K:K,'Closed SF Cases MTD'!Z:Z,0) -> 865 | H5: =_xlfn.XLOOKUP(E5,BI!C:C,BI!M:M,0) -> 10 | J5: Alissa Caskey | N5: 36 | P5: 6 | R5: 42 | T5: Alissa Caskey | U5: 3 | V5: 41 | W5: 27 | Y5: 2 | AA5: 17 | AB5: 3 | AD5: 2 | AE5: 1 | AG5: 2 | AI5: 98
E6: Demetra Rainey | F6: =COUNTIF('Open SF cases MTD'!A:A,DashBoard!E6) -> 16 | G6: =_xlfn.XLOOKUP(E6,'Closed SF Cases MTD'!K:K,'Closed SF Cases MTD'!Z:Z,0) -> 77 | H6: =_xlfn.XLOOKUP(E6,BI!C:C,BI!M:M,0) -> 2 | J6: Alyssa Torres | L6: 1 | N6: 1 | R6: 2 | T6: Alyssa Torres | V6: 1 | AA6: 1 | AI6: 2
E7: Dessie Temple | F7: =COUNTIF('Open SF cases MTD'!A:A,DashBoard!E7) -> 35 | G7: =_xlfn.XLOOKUP(E7,'Closed SF Cases MTD'!K:K,'Closed SF Cases MTD'!Z:Z,0) -> 317 | H7: =_xlfn.XLOOKUP(E7,BI!C:C,BI!M:M,0) -> 4 | J7: Andrew Henderson | K7: 31 | N7: 2 | R7: 33 | T7: Asante Msosa | Y7: 24 | Z7: 7 | AA7: 4 | AB7: 2 | AC7: 5 | AE7: 59 | AH7: 21 | AI7: 122
E8: Joshua Ball | F8: =COUNTIF('Open SF cases MTD'!A:A,DashBoard!E8) -> 5 | G8: =_xlfn.XLOOKUP(E8,'Closed SF Cases MTD'!K:K,'Closed SF Cases MTD'!Z:Z,0) -> 13 | H8: =_xlfn.XLOOKUP(E8,BI!C:C,BI!M:M,0) -> 16 | J8: Asante Msosa | K8: 5 | N8: 17 | P8: 5 | R8: 27 | T8: Barb Phillips | V8: 3 | W8: 2 | Y8: 2 | Z8: 10 | AA8: 3 | AC8: 6 | AE8: 29 | AF8: 1 | AH8: 3 | AI8: 59
E9: Margaret Reddy | F9: =COUNTIF('Open SF cases MTD'!A:A,DashBoard!E9) -> 20 | G9: =_xlfn.XLOOKUP(E9,'Closed SF Cases MTD'!K:K,'Closed SF Cases MTD'!Z:Z,0) -> 32 | H9: =_xlfn.XLOOKUP(E9,BI!C:C,BI!M:M,0) -> 3 | J9: Barb Phillips | K9: 10 | N9: 1 | O9: 3 | P9: 1 | R9: 15 | T9: Brooke Elizabeth Stafford | AH9: 1 | AI9: 1
E10: Michael McSharry | F10: =COUNTIF('Open SF cases MTD'!A:A,DashBoard!E10) -> 8 | G10: =_xlfn.XLOOKUP(E10,'Closed SF Cases MTD'!K:K,'Closed SF Cases MTD'!Z:Z,0) -> 7 | H10: =_xlfn.XLOOKUP(E10,BI!C:C,BI!M:M,0) -> 14 | J10: Bavani Corrie | K10: 185 | N10: 2 | R10: 187 | T10: Christina J Harris | U10: 6 | V10: 31 | W10: 47 | Z10: 18 | AA10: 14 | AC10: 1 | AE10: 126 | AF10: 2 | AG10: 1 | AH10: 4 | AI10: 250
E11: Nancy Cleveland | F11: =COUNTIF('Open SF cases MTD'!A:A,DashBoard!E11) -> 14 | G11: =_xlfn.XLOOKUP(E11,'Closed SF Cases MTD'!K:K,'Closed SF Cases MTD'!Z:Z,0) -> 93 | H11: =_xlfn.XLOOKUP(E11,BI!C:C,BI!M:M,0) -> 12 | J11: Brooke Elizabeth Stafford | T11: Clarene Stapleton | U11: 27 | V11: 2 | W11: 533 | Z11: 9 | AA11: 90 | AB11: 1 | AC11: 137 | AE11: 29 | AG11: 29 | AH11: 8 | AI11: 865
E12: Perry Young | F12: =COUNTIF('Open SF cases MTD'!A:A,DashBoard!E12) -> 13 | G12: =_xlfn.XLOOKUP(E12,'Closed SF Cases MTD'!K:K,'Closed SF Cases MTD'!Z:Z,0) -> 10 | H12: =_xlfn.XLOOKUP(E12,BI!C:C,BI!M:M,0) -> 14 | J12: Christina J Harris | K12: 6 | L12: 6 | N12: 10 | R12: 22 | T12: Colleen Nash | U12: 1 | V12: 3 | AA12: 1 | AC12: 1 | AH12: 14 | AI12: 20
J13: Clarene Stapleton | L13: 38 | N13: 2 | R13: 40 | T13: Corey Krause | U13: 6 | V13: 109 | W13: 35 | Z13: 2 | AA13: 29 | AB13: 1 | AC13: 3 | AE13: 4 | AG13: 9 | AH13: 4 | AI13: 202
J14: Colleen Nash | K14: 1 | L14: 3 | N14: 2 | R14: 6 | T14: Cyn H | Z14: 1 | AI14: 1
E15: Case Type | J15: Corey Krause | K15: 9 | N15: 24 | R15: 33 | T15: Data Protection | AH15: 3 | AI15: 3
J16: Cyn H | N16: 1 | R16: 1 | T16: Debra Anis | V16: 2 | W16: 1 | Y16: 16 | Z16: 4 | AA16: 2 | AB16: 6 | AC16: 4 | AE16: 28 | AH16: 23 | AI16: 86
J17: Debra Anis | K17: 24 | N17: 1 | P17: 12 | R17: 37 | T17: Demetra Rainey | V17: 1 | W17: 11 | Y17: 3 | Z17: 15 | AA17: 3 | AB17: 2 | AC17: 1 | AE17: 36 | AG17: 1 | AH17: 4 | AI17: 77
E18: Open | F18: 1 | J18: Demetra Rainey | K18: 4 | L18: 11 | N18: 1 | R18: 16 | T18: Dessie Temple | U18: 6 | V18: 20 | W18: 173 | Y18: 5 | Z18: 10 | AA18: 26 | AC18: 13 | AE18: 12 | AG18: 9 | AH18: 43 | AI18: 317
E19: Case Owner | F19: Standard Priority Cases | J19: Dessie Temple | K19: 9 | L19: 2 | N19: 15 | R19: 26 | T19: Diana C | V19: 3 | W19: 9 | Y19: 33 | Z19: 28 | AA19: 3 | AB19: 4 | AC19: 2 | AE19: 22 | AH19: 23 | AI19: 127
J20: Diana C | K20: 30 | L20: 3 | N20: 35 | O20: 1 | P20: 8 | R20: 77 | T20: Dianna Resendez | AB20: 2 | AC20: 99 | AH20: 12 | AI20: 113
E21: Row Labels | F21: Count of Status | G21: % of Open | J21: Dianna Resendez | K21: 30 | L21: 171 | R21: 201 | T21: Gia Stinson | U21: 3 | V21: 38 | W21: 35 | AA21: 21 | AB21: 6 | AC21: 2 | AD21: 3 | AG21: 3 | AI21: 111
E22: Account Support | F22: 2 | G22: 0.0044843049 | J22: Gia Stinson | K22: 30 | L22: 2 | N22: 19 | R22: 51 | T22: High Priority Cases | V22: 1 | AI22: 1
E23: Billing | F23: 37 | G23: 0.082959641 | J23: Joshua Ball | K23: 4 | L23: 1 | R23: 5 | T23: Joshua Ball | V23: 3 | W23: 2 | AA23: 1 | AE23: 3 | AH23: 4 | AI23: 13
E24: Cancel Plan | F24: 24 | G24: 0.053811659 | J24: Kamry Williams | T24: Kimberly Teasley | U24: 1 | V24: 2 | W24: 2 | Z24: 13 | AA24: 12 | AB24: 2 | AC24: 14 | AE24: 55 | AH24: 1 | AI24: 102
E25: Out of Network Repair | F25: 37 | G25: 0.082959641 | J25: Kimberly Teasley | K25: 10 | L25: 1 | N25: 40 | P25: 1 | R25: 52 | T25: Magdalena Leon | W25: 1 | Z25: 3 | AC25: 1 | AE25: 1 | AH25: 10 | AI25: 16
E26: Parts | F26: 59 | G26: 0.132287 | J26: Magdalena Leon | K26: 4 | R26: 4 | T26: Margaret Reddy | Z26: 9 | AC26: 1 | AE26: 22 | AI26: 32
E27: Plan Support | F27: 15 | G27: 0.033632287 | J27: Margaret Reddy | K27: 5 | L27: 6 | N27: 4 | P27: 5 | R27: 20 | T27: Melissa Orosco | AC27: 222 | AE27: 1 | AH27: 4 | AI27: 227
E28: Repair Authorization | F28: 1 | G28: 0.0022421525 | J28: Melissa Orosco | K28: 43 | L28: 100 | N28: 7 | R28: 150 | T28: Michael McSharry | V28: 1 | W28: 2 | AA28: 1 | AF28: 1 | AH28: 2 | AI28: 7
E29: Replacement | F29: 12 | G29: 0.02690583 | J29: Michael McSharry | L29: 6 | R29: 6 | T29: Nancy Cleveland | U29: 1 | V29: 7 | W29: 6 | Y29: 4 | Z29: 9 | AA29: 28 | AB29: 1 | AC29: 9 | AD29: 3 | AE29: 19 | AH29: 6 | AI29: 93
E30: Retention | F30: 2 | G30: 0.0044843049 | J30: Nancy Cleveland | L30: 10 | N30: 1 | R30: 11 | T30: Nicole Erickson | U30: 2 | V30: 41 | W30: 1 | Z30: 4 | AA30: 2 | AB30: 5 | AE30: 2 | AH30: 8 | AI30: 65
E31: Service Request | F31: 164 | G31: 0.367713 | J31: New Complaints | N31: 4 | R31: 4 | T31: Paaton Howard | V31: 1 | W31: 1 | Y31: 30 | Z31: 9 | AB31: 1 | AC31: 3 | AE31: 75 | AF31: 3 | AG31: 2 | AH31: 22 | AI31: 147
E32: SR Mapping Research | F32: 15 | G32: 0.033632287 | J32: Nicole Erickson | K32: 16 | L32: 4 | N32: 4 | P32: 2 | R32: 26 | T32: Perry Young | Z32: 3 | AE32: 7 | AI32: 10
E33: Web/Portal Support | F33: 5 | G33: 0.011210762 | J33: Paaton Howard | K33: 4 | N33: 2 | R33: 6 | T33: Return Mail Followup | AA33: 87 | AI33: 87
E34: (blank) | F34: 73 | G34: 0.16367713 | J34: Perry Young | L34: 13 | R34: 13 | T34: Rosa Scott-Duren | W34: 1 | Y34: 17 | Z34: 5 | AB34: 4 | AC34: 16 | AE34: 35 | AH34: 16 | AI34: 94
E35: Grand Total | F35: 446 | G35: 1 | J35: Product Replacements | N35: 39 | R35: 39 | T35: Shelby Bickford | V35: 1 | W35: 2 | AA35: 6 | AB35: 1 | AG35: 2 | AH35: 2 | AI35: 14
J36: Quinn Graham | T36: Standard Priority Cases | U36: 200 | V36: 131 | W36: 16 | X36: 2 | Y36: 6 | Z36: 11 | AA36: 22 | AB36: 130 | AC36: 77 | AE36: 102 | AF36: 342 | AG36: 6 | AH36: 321 | AI36: 1366
J37: Rosa Scott-Duren | K37: 28 | N37: 2 | P37: 13 | R37: 43 | T37: Steven Yanis | V37: 1 | AE37: 1 | AH37: 2 | AI37: 4
J38: Service Watch | K38: 1 | N38: 1 | R38: 2 | T38: Tomekia (Ms. T) H. | U38: 1 | W38: 1 | Y38: 2 | AA38: 1 | AC38: 5 | AE38: 9 | AH38: 17 | AI38: 36
J39: Shanna Richards | T39: Vickie Phillips-Wall | U39: 1 | V39: 1 | W39: 3 | Y39: 3 | Z39: 9 | AA39: 2 | AB39: 1 | AC39: 7 | AE39: 13 | AG39: 8 | AH39: 72 | AI39: 120
J40: Shelby Bickford | T40: Web Cancel Requests | W40: 1 | AI40: 1
...

Sheet Sheet3
B3: {=_xlfn.LET( _xlpm.TargetAssociates, {"Alyssa Torres";"Christina J Harris";"Clarene Stapleton";"Demetra Rainey";"Dessie Temple";"Joshua Bell";"Margaret Reddy";"Michael McSharry";"Nancy Cleveland";"Perry Young"}, _xlpm.Owners, 'Closed SF Cases MTD'!A2:A10000, _xlpm.Status, 'Closed SF Cases MTD'!D2:D10000, _xlpm.Dates, 'Closed SF Cases MTD'!H2:H10000, _xlpm.Filtered, _xlfn._xlws.FILTER(_xlpm.Owners, (_xlpm.Status="Closed") * (INT(_xlpm.Dates)=TODAY()) * ISNUMBER(MATCH(_xlpm.Owners, _xlpm.TargetAssociates, 0))), _xlpm.CountTable, _xlfn.UNIQUE(_xlpm.Filtered), _xlpm.Counts, _xlfn.MAP(_xlpm.CountTable, _xlfn.LAMBDA(_xlpm.a, COUNTIF(_xlpm.Filtered, _xlpm.a))), _xlpm.Sorted, _xlfn._xlws.SORT(_xlfn.HSTACK(_xlpm.CountTable, _xlpm.Counts), 2, -1), _xlfn.TAKE(_xlpm.Sorted, 10) )} -> #VALUE! | F3: {=_xlfn.LET( _xlpm.TargetAssociates, {"Alyssa Torres";"Christina J Harris";"Clarene Stapleton";"Demetra Rainey";"Dessie Temple";"Joshua Bell";"Margaret Reddy";"Michael McSharry";"Nancy Cleveland";"Perry Young"}, _xlpm.Owners, 'Closed SF Cases MTD'!A2:A10000, _xlpm.Status, 'Closed SF Cases MTD'!D2:D10000, _xlpm.Filtered, _xlfn._xlws.FILTER(_xlpm.Owners, (_xlpm.Status="Closed") * ISNUMBER(MATCH(_xlpm.Owners, _xlpm.TargetAssociates, 0))), _xlpm.CountTable, _xlfn.UNIQUE(_xlpm.Filtered), _xlpm.Counts, _xlfn.MAP(_xlpm.CountTable, _xlfn.LAMBDA(_xlpm.a, COUNTIF(_xlpm.Filtered, _xlpm.a))), _xlpm.Sorted, _xlfn._xlws.SORT(_xlfn.HSTACK(_xlpm.CountTable, _xlpm.Counts), 2, -1), _xlfn.TAKE(_xlpm.Sorted, 10) )} -> #VALUE!

Sheet Sheet1
A1: case# | B1: cx ph# | C1: case type | D1: case Desc | E1: Next Steps
A2: 12345 | B2: 12345678 | C2: Billing | D2: whatever | E2: Test

Sheet lists and dropdowns
A1: Account Support
A2: Billing
A3: Cancel Plan
A4: Out of Network Repair
A5: Parts
A6: Plan Support
A7: Repair Authorization
A8: Replacement
A9: Retention
A10: Service Request
A11: SR Mapping Research
A12: Web/Portal Support

Sheet Open SF cases MTD
A1: Case Owner | B1: Subject | C1: Account Name | D1: Opened Date | E1: Person Account: Home Phone | F1: Case Number | G1: Status | I1: Count of Account Name | J1: Column Labels
A2: Tomekia (Ms. T) H. | B2: Parts- Follow up with TPD and Cx on 12-11-25 (Barb) | C2: Elizabeth Sturm | D2: 45967 | E2: 7657164178 | F2: 271846 | G2: New | I2: Row Labels | J2: In Process | K2: In Progress | L2: In Review | M2: New | N2: New Complaint | O2: On Hold | P2: (blank) | Q2: Grand Total
A3: Steven Yanis | B3: [CEO Complaint] Refrigerator Repair TPD & CX follow-up | C3: Jamie Jackson | D3: 46178 | E3: 8186218043 | F3: 388285 | G3: New | I3: Admin Tasks | M3: 26 | Q3: 26
A4: Tomekia (Ms. T) H. | B4: CX will take legal action if he doesn't gets any updates from D&G | C4: Jason Angone | D4: 46181 | E4: 6306392351 | F4: 388577 | G4: New | I4: Alissa Caskey | M4: 36 | O4: 6 | Q4: 42
A5: Tomekia (Ms. T) H. | B5: Service Request-SR research-f/u needed on next steps after last repair on washer | C5: Carl Williams | D5: 46203 | F5: 394222 | G5: New | I5: Alyssa Torres | K5: 1 | M5: 1 | Q5: 2
A6: Tomekia (Ms. T) H. | B6: Service Request-SR research-cx threating with lawyer | C6: Karen Kennedy | D6: 46213 | F6: 396771 | G6: New | I6: Andrew Henderson | J6: 31 | M6: 2 | Q6: 33
A7: Tomekia (Ms. T) H. | B7: Service Request-SR research Complaint | C7: Dianne Apter-Mckay | D7: 46216 | F7: 397013 | G7: New | I7: Asante Msosa | J7: 5 | M7: 17 | O7: 5 | Q7: 27
A8: New Complaints | B8: Service Request-Find service tech-Cx claims fraud after pay and claim was offered. Going to Lawyer | C8: Elizabeth Benet | D8: 46223 | E8: 3344883417 | F8: 398688 | G8: New | I8: Barb Phillips | J8: 10 | M8: 1 | N8: 3 | O8: 1 | Q8: 15
A9: New Complaints | B9: Billing-Billing Inquiry-Account holder is deceased. Estate is closed. Removed cx from contact list | C9: Richard Morris | D9: 46223 | E9: 3369609420 | F9: 398983 | G9: New | I9: Bavani Corrie | J9: 185 | M9: 2 | Q9: 187
A10: Tomekia (Ms. T) H. | B10: Service Request-BBB Complaint 25060787 Refrigerator Repair | C10: William Sampson | D10: 46224 | F10: 399215 | G10: New | I10: Brooke Elizabeth Stafford
A11: New Complaints | B11: Service Request-SR research-Washer Open SR 2 Months Needs Followup | C11: Roger Atkinson | D11: 46225 | F11: 399439 | G11: New | I11: Christina J Harris | J11: 6 | K11: 6 | M11: 10 | Q11: 22
A12: New Complaints | B12: Parts-Parts on Order-cx called to say parts on order since 3 weeks as against 2 weeks tech said Cx requested that A supervisor Call back | C12: Melanie Skinner | D12: 46225 | E12: 8043669116 | F12: 399554 | G12: New | I12: Clarene Stapleton | K12: 38 | M12: 2 | Q12: 40
A13: Cyn H | B13: Replacement for Refrigerator, Top Mount | C13: BOBBIE HUNTER | D13: 45391 | E13: 9845690552 | F13: 47952 | G13: New | I13: Colleen Nash | J13: 1 | K13: 3 | M13: 2 | Q13: 6
A14: Andrew Henderson | B14: Plans did not properly bundle for payment causing collection failures. | C14: Maritza Velasquez | D14: 45443 | E14: 8324880183 | F14: 63460 | G14: New | I14: Corey Krause | J14: 9 | M14: 24 | Q14: 33
A15: Andrew Henderson | B15: Plans did not properly bundle for payment causing collection failures. | C15: Kathy Kritzer | D15: 45443 | F15: 61298 | G15: New | I15: Cyn H | M15: 1 | Q15: 1
A16: Bavani Corrie | B16: Cancel Plan-Failed Payments on plan-Duplicate plans have been cancelled. | C16: Taylor Alvarez | D16: 45917 | E16: 9037676577 | F16: 242073 | G16: New | I16: Debra Anis | J16: 24 | M16: 1 | O16: 12 | Q16: 37
A17: Bavani Corrie | B17: Cancel Plan-Other-Duplicate plan has been cancelled. | C17: Sonia Prestemon | D17: 45966 | F17: 270972 | G17: New | I17: Demetra Rainey | J17: 4 | K17: 11 | M17: 1 | Q17: 16
A18: Alissa Caskey | B18: Pending cx SOT | C18: Ralph Jones | D18: 45999 | F18: 290155 | G18: New | I18: Dessie Temple | J18: 9 | K18: 2 | M18: 15 | Q18: 26
A19: Gia Stinson | B19: Replacement-Other-cx had 3 sr same issue unit not fixed | C19: Sandra Wash | D19: 46017 | E19: 2108432178 | F19: 299600 | G19: New | I19: Diana C | J19: 30 | K19: 3 | M19: 35 | N19: 1 | O19: 8 | Q19: 77
A20: Melissa Orosco | B20: Replacement scheduled to arrive 5/14, wp, wp form | C20: Ajah Peace | D20: 46104 | F20: 345964 | G20: New | I20: Dianna Resendez | J20: 30 | K20: 171 | Q20: 201
A21: Brooke Elizabeth Stafford | B21: Allie Egerer from Domestic & General (Hub 6413964) has invited you to HubSpot | D21: 46132 | F21: 375213 | G21: New | I21: Gia Stinson | J21: 30 | K21: 2 | M21: 19 | Q21: 51
A22: Brooke Elizabeth Stafford | B22: HubSpot Account | D22: 46132 | F22: 375358 | G22: New | I22: Joshua Ball | J22: 4 | K22: 1 | Q22: 5
A23: Alissa Caskey | B23: Pending finance task | C23: Mervic Gil | D23: 46135 | E23: 3057986504 | F23: 376772 | G23: New | I23: Kamry Williams
A24: Diana C | B24: SOT | | C24: Linda Lewis | D24: 46139 | E24: 5178125216 | F24: 377643 | G24: New | I24: Kimberly Teasley | J24: 10 | K24: 1 | M24: 40 | O24: 1 | Q24: 52
A25: Steven Yanis | B25: CLAIM DISPUTE /Start date /10/10/2025 | C25: Vallia Huff | D25: 46146 | F25: 380410 | G25: New | I25: Magdalena Leon | J25: 4 | Q25: 4
A26: Alyssa Torres | B26: Replacement-Subsequent repair BER-Possible BER/ Tech just left, and washer is worse than before | C26: Clara Vanessa Valles Flores | D26: 46153 | E26: 9414656612 | F26: 382220 | G26: New | I26: Margaret Reddy | J26: 5 | K26: 6 | M26: 4 | O26: 5 | Q26: 20
A27: Christina J Harris | B27: Fridge: Confirmed BER -- 2nd email sent | C27: Craig Benendetti | D27: 46161 | F27: 384252 | G27: New | I27: Melissa Orosco | J27: 43 | K27: 100 | M27: 7 | Q27: 150
A28: Alissa Caskey | B28: Pending TPD response | D28: 46164 | F28: 384897 | G28: New | I28: Michael McSharry | K28: 6 | Q28: 6
A29: Demetra Rainey | B29: Service Request-SR research-Potential BER follow up 7.28 | C29: BILLY AALAND-PARRISH | D29: 46168 | E29: 9707788357 | F29: 385574 | G29: New | I29: Nancy Cleveland | K29: 10 | M29: 1 | Q29: 11
A30: Diana C | B30: Fw: Invoice | D30: 46170 | F30: 386137 | G30: New | I30: New Complaints | M30: 4 | Q30: 4
A31: Nicole Erickson | B31: Billing-Billing Inquiry-WP Refund for ACT- Cx provided # to WP. Closing case. | C31: Victor Preciado | D31: 46178 | F31: 388122 | G31: New | I31: Nicole Erickson | J31: 16 | K31: 4 | M31: 4 | O31: 2 | Q31: 26
A32: Diana C | B32: **SPANISH** | fu 07.20 FOLLOW UP | C32: Erika Trevino | D32: 46181 | F32: 388742 | G32: New | I32: Paaton Howard | J32: 4 | M32: 2 | Q32: 6
A33: Melissa Orosco | B33: Replacement scheduled to arrive 7/21, Lowes | C33: Joseph Dutcheshen | D33: 46182 | F33: 389073 | G33: New | I33: Perry Young | K33: 13 | Q33: 13
A34: Melissa Orosco | B34: Re: When repair isn?t possible, replacement is our promise. | C34: Joseph Dutcheshen | D34: 46184 | F34: 389570 | G34: New | I34: Product Replacements | M34: 39 | Q34: 39
A35: Margaret Reddy | B35: Parts-Parts on Order-Parts ordered 4 weeks ago. Ghosted by SP | C35: Diann Dixon | D35: 46185 | F35: 389951 | G35: New | I35: Quinn Graham
A36: Alissa Caskey | B36: Pending TPD response | C36: Emily Kemnitz | D36: 46185 | F36: 389979 | G36: New | I36: Rosa Scott-Duren | J36: 28 | M36: 2 | O36: 13 | Q36: 43
A37: Alissa Caskey | B37: Need to cancel plan got WIB error | D37: 46187 | F37: 390181 | G37: New | I37: Service Watch | J37: 1 | M37: 1 | Q37: 2
A38: Quinn Graham | B38: Re: << Ref:1002857 >> D&G Plan Cancellation Options | D38: 46189 | F38: 390889 | G38: New | I38: Shanna Richards
A39: Quinn Graham | B39: Case # 1006192 Plan # DG0102851040 | D39: 46189 | F39: 390899 | G39: New | I39: Shelby Bickford
A40: Alissa Caskey | B40: Pending TPD response | C40: Teresa Dargan | D40: 46190 | F40: 391061 | G40: New | I40: Standard Priority Cases | J40: 5 | M40: 343 | Q40: 348
...

Sheet Closed SF Cases MTD
A1: Case Owner | B1: Subject | C1: Account Name | D1: Status | E1: Person Account: Home Phone | F1: Case Number | G1: Case Last Modified By | H1: Date/Time Closed | I1: Type | K1: Count of Status | L1: Column Labels
A2: Standard Priority Cases | B2: Warranty payment | D2: Closed | F2: 394021 | G2: Colleen Nash | H2: 7/1/2026, 3:13 AM | K2: Row Labels | L2: Account Support | M2: Billing | N2: Cancel Plan | O2: Email Third Party Escalations | P2: Out of Network Repair | Q2: Parts | R2: Plan Support | S2: Repair Authorization | T2: Replacement | U2: Retention | V2: Service Request | W2: SR Mapping Research | X2: Web/Portal Support | Y2: (blank) | Z2: Grand Total
A3: Standard Priority Cases | B3: Case#00392432 | D3: Closed | F3: 394071 | G3: Colleen Nash | H3: 7/1/2026, 3:13 AM | K3: Admin Tasks | R3: 1 | Y3: 1715 | Z3: 1716
A4: Standard Priority Cases | D4: Closed | F4: 394079 | G4: Colleen Nash | H4: 7/1/2026, 3:17 AM | K4: Alissa Caskey | L4: 3 | M4: 41 | N4: 27 | P4: 2 | R4: 17 | S4: 3 | U4: 2 | V4: 1 | X4: 2 | Z4: 98
A5: Standard Priority Cases | B5: Re: Case # 00393738 | D5: Closed | F5: 394238 | G5: Colleen Nash | H5: 7/1/2026, 3:20 AM | K5: Alyssa Torres | M5: 1 | R5: 1 | Z5: 2
A6: Standard Priority Cases | B6: Re:Gillian Corbie - cancellation | D6: Closed | F6: 394091 | G6: Colleen Nash | H6: 7/1/2026, 3:20 AM | K6: Asante Msosa | P6: 24 | Q6: 7 | R6: 4 | S6: 2 | T6: 5 | V6: 59 | Y6: 21 | Z6: 122
A7: Standard Priority Cases | B7: Providing information | D7: Closed | F7: 394273 | G7: Colleen Nash | H7: 7/1/2026, 3:21 AM | K7: Barb Phillips | M7: 3 | N7: 2 | P7: 2 | Q7: 10 | R7: 3 | T7: 6 | V7: 29 | W7: 1 | Y7: 3 | Z7: 59
A8: Standard Priority Cases | B8: FW: Cancellation Confirmation ? D&G Appliance Protection Plan | D8: Closed | F8: 394132 | G8: Colleen Nash | H8: 7/1/2026, 3:22 AM | K8: Brooke Elizabeth Stafford | Y8: 1 | Z8: 1
A9: Standard Priority Cases | B9: Question about my billing | D9: Closed | F9: 394186 | G9: Colleen Nash | H9: 7/1/2026, 3:27 AM | K9: Christina J Harris | L9: 6 | M9: 31 | N9: 47 | Q9: 18 | R9: 14 | T9: 1 | V9: 126 | W9: 2 | X9: 1 | Y9: 4 | Z9: 250
A10: Standard Priority Cases | B10: Update payment details | D10: Closed | F10: 394245 | G10: Colleen Nash | H10: 7/1/2026, 3:31 AM | K10: Clarene Stapleton | L10: 27 | M10: 2 | N10: 533 | Q10: 9 | R10: 90 | S10: 1 | T10: 137 | V10: 29 | X10: 29 | Y10: 8 | Z10: 865
A11: Standard Priority Cases | B11: You have new held messages | D11: Closed | F11: 394276 | G11: Colleen Nash | H11: 7/1/2026, 3:32 AM | K11: Colleen Nash | L11: 1 | M11: 3 | R11: 1 | T11: 1 | Y11: 14 | Z11: 20
A12: Dessie Temple | B12: Attention Ms T & Ms Vickie | D12: Closed | F12: 394209 | G12: Dessie Temple | H12: 7/1/2026, 5:02 AM | K12: Corey Krause | L12: 6 | M12: 109 | N12: 35 | Q12: 2 | R12: 29 | S12: 1 | T12: 3 | V12: 4 | X12: 9 | Y12: 4 | Z12: 202
A13: Colleen Nash | B13: Cancel policy?s | D13: Closed | F13: 393300 | G13: Colleen Nash | H13: 7/1/2026, 5:32 AM | K13: Cyn H | Q13: 1 | Z13: 1
A14: Colleen Nash | B14: Close accounts | D14: Closed | F14: 393330 | G14: Colleen Nash | H14: 7/1/2026, 5:33 AM | K14: Data Protection | Y14: 3 | Z14: 3
A15: Diana C | B15: RELAY TO CASE#00312519 | D15: Closed | F15: 394180 | G15: Diana C | H15: 7/1/2026, 5:42 AM | K15: Debra Anis | M15: 2 | N15: 1 | P15: 16 | Q15: 4 | R15: 2 | S15: 6 | T15: 4 | V15: 28 | Y15: 23 | Z15: 86
A16: Vickie Phillips-Wall | B16: Service- Service is scheduled for 7/3 w/Sears | C16: Melissa Hartman | D16: Closed | F16: 391473 | G16: Vickie Phillips-Wall | H16: 7/1/2026, 6:10 AM | K16: Demetra Rainey | M16: 1 | N16: 11 | P16: 3 | Q16: 15 | R16: 3 | S16: 2 | T16: 1 | V16: 36 | X16: 1 | Y16: 4 | Z16: 77
A17: Magdalena Leon | B17: Plan cancelled on WIB case 1007689 | D17: Closed | F17: 394216 | G17: Magdalena Leon | H17: 7/1/2026, 6:18 AM | K17: Dessie Temple | L17: 6 | M17: 20 | N17: 173 | P17: 5 | Q17: 10 | R17: 26 | T17: 13 | V17: 12 | X17: 9 | Y17: 43 | Z17: 317
A18: Vickie Phillips-Wall | B18: WIB Case #1009160- Plan and SR cancelled | D18: Closed | F18: 391415 | G18: Vickie Phillips-Wall | H18: 7/1/2026, 6:25 AM | K18: Diana C | M18: 3 | N18: 9 | P18: 33 | Q18: 28 | R18: 3 | S18: 4 | T18: 2 | V18: 22 | Y18: 23 | Z18: 127
A19: Vickie Phillips-Wall | B19: Case # 1008056 | D19: Closed | F19: 391560 | G19: Vickie Phillips-Wall | H19: 7/1/2026, 6:43 AM | K19: Dianna Resendez | S19: 2 | T19: 99 | Y19: 12 | Z19: 113
A20: Vickie Phillips-Wall | B20: lack of good service | D20: Closed | F20: 391574 | G20: Vickie Phillips-Wall | H20: 7/1/2026, 6:50 AM | K20: Gia Stinson | L20: 3 | M20: 38 | N20: 35 | R20: 21 | S20: 6 | T20: 2 | U20: 3 | X20: 3 | Z20: 111
A21: Dessie Temple | B21: Hello | D21: Closed | F21: 393606 | G21: Dessie Temple | H21: 7/1/2026, 6:53 AM | K21: High Priority Cases | M21: 1 | Z21: 1
A22: Vickie Phillips-Wall | B22: Change Email Address | D22: Closed | F22: 391846 | G22: Vickie Phillips-Wall | H22: 7/1/2026, 6:59 AM | K22: Joshua Ball | M22: 3 | N22: 2 | R22: 1 | V22: 3 | Y22: 4 | Z22: 13
A23: Vickie Phillips-Wall | B23: Cancellation of policies | D23: Closed | F23: 391742 | G23: Vickie Phillips-Wall | H23: 7/1/2026, 7:01 AM | K23: Kimberly Teasley | L23: 1 | M23: 2 | N23: 2 | Q23: 13 | R23: 12 | S23: 2 | T23: 14 | V23: 55 | Y23: 1 | Z23: 102
A24: Diana C | B24: REPLACEMENT case 00392843 | REFUND SOT case#00392550 | D24: Closed | F24: 394272 | G24: Diana C | H24: 7/1/2026, 7:06 AM | K24: Magdalena Leon | N24: 1 | Q24: 3 | T24: 1 | V24: 1 | Y24: 10 | Z24: 16
A25: Vickie Phillips-Wall | B25: Service- Per TPD/SP the service was completed on 6/23 WIB Case#1009161 | D25: Closed | F25: 391897 | G25: Vickie Phillips-Wall | H25: 7/1/2026, 7:17 AM | K25: Margaret Reddy | Q25: 9 | T25: 1 | V25: 22 | Z25: 32
A26: Vickie Phillips-Wall | B26: Plan Number 62W0000613 | D26: Closed | F26: 392097 | G26: Vickie Phillips-Wall | H26: 7/1/2026, 8:02 AM | K26: Melissa Orosco | T26: 222 | V26: 1 | Y26: 4 | Z26: 227
A27: Vickie Phillips-Wall | B27: WIB Case#1007598-Out of Network Reimbursement | D27: Closed | F27: 392132 | G27: Vickie Phillips-Wall | H27: 7/1/2026, 8:21 AM | K27: Michael McSharry | M27: 1 | N27: 2 | R27: 1 | W27: 1 | Y27: 2 | Z27: 7
A28: Vickie Phillips-Wall | B28: Service- Unit was not deemed unrepairable need to be rescheduled-CASE #1006242 | D28: Closed | F28: 392339 | G28: Vickie Phillips-Wall | H28: 7/1/2026, 8:56 AM | K28: Nancy Cleveland | L28: 1 | M28: 7 | N28: 6 | P28: 4 | Q28: 9 | R28: 28 | S28: 1 | T28: 9 | U28: 3 | V28: 19 | Y28: 6 | Z28: 93
A29: Paaton Howard | B29: Fw: Quote from Farr's Hardware - 06/17/2026 | C29: Kerry Cavanagh | D29: Closed | F29: 392550 | G29: Paaton Howard | H29: 7/1/2026, 9:01 AM | K29: Nicole Erickson | L29: 2 | M29: 41 | N29: 1 | Q29: 4 | R29: 2 | S29: 5 | V29: 2 | Y29: 8 | Z29: 65
A30: Vickie Phillips-Wall | B30: Fw: PLAN NUMBER J2Z0094851 | D30: Closed | F30: 392396 | G30: Vickie Phillips-Wall | H30: 7/1/2026, 9:14 AM | K30: Paaton Howard | M30: 1 | N30: 1 | P30: 30 | Q30: 9 | S30: 1 | T30: 3 | V30: 75 | W30: 3 | X30: 2 | Y30: 22 | Z30: 147
A31: Standard Priority Cases | B31: Verified Review Support | D31: Closed | F31: 394341 | G31: Colleen Nash | H31: 7/1/2026, 9:41 AM | K31: Perry Young | Q31: 3 | V31: 7 | Z31: 10
A32: Standard Priority Cases | B32: You have new held messages | D32: Closed | F32: 394362 | G32: Colleen Nash | H32: 7/1/2026, 9:42 AM | K32: Return Mail Followup | R32: 87 | Z32: 87
A33: Standard Priority Cases | B33: Stolen money | D33: Closed | F33: 394331 | G33: Colleen Nash | H33: 7/1/2026, 9:43 AM | K33: Rosa Scott-Duren | N33: 1 | P33: 17 | Q33: 5 | S33: 4 | T33: 16 | V33: 35 | Y33: 16 | Z33: 94
A34: Standard Priority Cases | B34: Your message couldn't be delivered | D34: Closed | F34: 394334 | G34: Colleen Nash | H34: 7/1/2026, 9:44 AM | K34: Shelby Bickford | M34: 1 | N34: 2 | R34: 6 | S34: 1 | X34: 2 | Y34: 2 | Z34: 14
A35: Standard Priority Cases | D35: Closed | F35: 394280 | G35: Colleen Nash | H35: 7/1/2026, 9:47 AM | K35: Standard Priority Cases | L35: 200 | M35: 131 | N35: 16 | O35: 2 | P35: 6 | Q35: 11 | R35: 22 | S35: 130 | T35: 77 | V35: 102 | W35: 342 | X35: 6 | Y35: 321 | Z35: 1366
A36: Standard Priority Cases | B36: Refrigerador whirpool | D36: Closed | F36: 394381 | G36: Colleen Nash | H36: 7/1/2026, 9:48 AM | K36: Steven Yanis | M36: 1 | V36: 1 | Y36: 2 | Z36: 4
A37: Standard Priority Cases | B37: DG0001772861 | D37: Closed | F37: 394351 | G37: Colleen Nash | H37: 7/1/2026, 9:50 AM | K37: Tomekia (Ms. T) H. | L37: 1 | N37: 1 | P37: 2 | R37: 1 | T37: 5 | V37: 9 | Y37: 17 | Z37: 36
A38: Standard Priority Cases | B38: Payment | D38: Closed | F38: 394377 | G38: Colleen Nash | H38: 7/1/2026, 9:51 AM | K38: Vickie Phillips-Wall | L38: 1 | M38: 1 | N38: 3 | P38: 3 | Q38: 9 | R38: 2 | S38: 1 | T38: 7 | V38: 13 | X38: 8 | Y38: 72 | Z38: 120
A39: Asante Msosa | B39: Dishwasher is not working again | D39: Closed | F39: 392664 | G39: Asante Msosa | H39: 7/1/2026, 10:42 AM | K39: Web Cancel Requests | N39: 1 | Z39: 1
A40: Asante Msosa | B40: addressed on case 00394414 | D40: Closed | F40: 392665 | G40: Asante Msosa | H40: 7/1/2026, 10:44 AM | K40: Yvanca Jackson | M40: 1 | N40: 1 | P40: 18 | Q40: 99 | R40: 8 | S40: 1 | V40: 15 | Y40: 68 | Z40: 211
...

Sheet Case Type
A1: Case Owner | B1: Subject | C1: Account Name | D1: Status | E1: Type | F1: Open | I1: Open | J1: 1
A2: Steven Yanis | B2: Formal Complaint ? Unresolved Claim and Unacceptable Customer Service: Catalina Camps | C2: Catalina Camps | D2: In Progress | F2: 1 | I2: Case Owner | J2: Standard Priority Cases
A3: Andrew Henderson | B3: Urgent: New payment method needed on account. | D3: In Process | F3: 1
A4: Andrew Henderson | B4: Urgent: New payment method needed on account. | D4: In Process | F4: 1 | I4: Row Labels | J4: Count of Status | K4: % of Open
A5: Andrew Henderson | B5: Urgent: New payment method needed on account. | D5: In Process | F5: 1 | I5: Account Support | J5: 2 | K5: 0.0044843049
A6: Andrew Henderson | B6: Urgent: New payment method needed on account. | D6: In Process | F6: 1 | I6: Billing | J6: 37 | K6: 0.082959641
A7: Andrew Henderson | B7: Urgent: New payment method needed on account. | D7: In Process | F7: 1 | I7: Cancel Plan | J7: 24 | K7: 0.053811659
A8: Andrew Henderson | B8: Urgent: New payment method needed on account. | D8: In Process | F8: 1 | I8: Out of Network Repair | J8: 37 | K8: 0.082959641
A9: Andrew Henderson | B9: Urgent: New payment method needed on account. | D9: In Process | F9: 1 | I9: Parts | J9: 59 | K9: 0.132287
A10: Andrew Henderson | B10: Urgent: New payment method needed on account. | D10: In Process | F10: 1 | I10: Plan Support | J10: 15 | K10: 0.033632287
A11: Andrew Henderson | B11: Urgent: New payment method needed on account. | D11: In Process | F11: 1 | I11: Repair Authorization | J11: 1 | K11: 0.0022421525
A12: Andrew Henderson | B12: Urgent: New payment method needed on account. | D12: In Process | F12: 1 | I12: Replacement | J12: 12 | K12: 0.02690583
A13: Andrew Henderson | B13: Urgent: New payment method needed on account. | D13: In Process | F13: 1 | I13: Retention | J13: 2 | K13: 0.0044843049
A14: Andrew Henderson | B14: Urgent: New payment method needed on account. | D14: In Process | F14: 1 | I14: Service Request | J14: 164 | K14: 0.367713
A15: Andrew Henderson | B15: Urgent: New payment method needed on account. | D15: In Process | F15: 1 | I15: SR Mapping Research | J15: 15 | K15: 0.033632287
A16: Andrew Henderson | B16: Urgent: New payment method needed on account. | D16: In Process | F16: 1 | I16: Web/Portal Support | J16: 5 | K16: 0.011210762
... A18: Andrew Henderson | B18: Urgent: New payment method needed on account. | D18: In Process | F18: 1 | I18: Grand Total | J18: 446 | K18: 1
A19: Andrew Henderson | B19: Urgent: New payment method needed on account. | D19: In Process | F19: 1
A20: Andrew Henderson | B20: Urgent: New payment method needed on account. | D20: In Process | F20: 1
A21: Andrew Henderson | B21: Urgent: New payment method needed on account. | D21: In Process | F21: 1
A22: Andrew Henderson | B22: Urgent: New payment method needed on account. | D22: In Process | F22: 1
A23: Andrew Henderson | B23: Urgent: New payment method needed on account. | D23: In Process | F23: 1
A24: Andrew Henderson | B24: Urgent: New payment method needed on account. | D24: In Process | F24: 1
A25: Andrew Henderson | B25: Urgent: New payment method needed on account. | D25: In Process | F25: 1
A26: Andrew Henderson | B26: Urgent: New payment method needed on account. | D26: In Process | F26: 1
A27: Andrew Henderson | B27: Urgent: New payment method needed on account. | D27: In Process | F27: 1
A28: Andrew Henderson | B28: Urgent: New payment method needed on account. | D28: In Process | F28: 1
A29: Andrew Henderson | B29: Urgent: New payment method needed on account. | D29: In Process | F29: 1
A30: Andrew Henderson | B30: Urgent: New payment method needed on account. | D30: In Process | F30: 1
... A116: Brooke Elizabeth Stafford | B116: Allie is still waiting for you to join their team at your company | D116: In Process | F116: 1
A117: Nicole Erickson | B117: SR Needed-WIB Plan Ref- SOT details sent to Cx, pending estimate. Follow up 6/11 | C117: Randall Barnes | D117: In Process | F117: 1
A118: Nicole Erickson | B118: Fwd: Central Kansas Appliance Repair- Pending call to TPD 7/22 | C118: Laura Pratt | D118: In Process | F118: 1
A119: Debra Anis | B119: Maytag Washer Issues. cx had service - job completed 6/16 - cx upset as he says panel was all scratched up by 1st servicer. Wants the panel replaced. | C119: JORGE LLODRA | D119: In Process | F119: 1
A120: Diana C | B120: Fw: Invoice | D120: New | F120: 1
A121: Melissa Orosco | B121: Re: When repair isn?t possible, replacement is our promise. | C121: Joseph Dutcheshen | D121: New | F121: 1
A122: Melissa Orosco | B122: Waiting for approval 7/6, 2nd attempt | C122: Haileigh Daniel | D122: In Progress | F122: 1
A123: Vickie Phillips-Wall | B123: Re: << Ref:1002713 >> WIB Case#1005124 Update on Parts | D123: In Process | F123: 1
A124: Tomekia (Ms. T) H. | B124: BBB Complaint # 25069490 Refrigerator Repair SR follow-up | C124: Heather lyons | D124: New | F124: 1
A125: Nicole Erickson | B125: Fwd: Whirlpool Purchase Confirmation- Plan in lapsed, Pending call to Cx 7/8 | C125: Robynn Smith | D125: In Process | F125: 1
A126: Cyn H | B126: Extended Warranty Account Issue follow up 6/29/25 | D126: In Process | F126: 1
...

Sheet WIB Cases
A1: CaseID | B1: CaseType | C1: CaseState | D1: StartedOn | E1: EndedOn | F1: FirstName | G1: LastName | H1: Username | K1: CaseState | L1: (All)
A2: 1010566 | B2: Cancel Plan | C2: New | D2: ################# | F2: Case | G2: API User | H2: case-service-acc
A3: 1011147 | B3: Service Request SR Research/Parts Research | C3: New | D3: ################# | F3: Perry | G3: Young | H3: Perry.Young@corp.spdatallc.com | K3: Row Labels | L3: Count of CaseID
A4: 1011148 | B4: Cancel Plan Open SR on Plan | C4: New | D4: ################# | F4: Brianna | G4: Totten | H4: Brianna.Totten@corp.spdatallc.com | K4: Account Support Bounce Email Follow Up | L4: 1
A5: 1011149 | B5: Plan Support Other | C5: New | D5: ################# | F5: Brianna | G5: Totten | H5: Brianna.Totten@corp.spdatallc.com | K5: Account Support Edit/Update Customer Info | L5: 1
A6: 1011550 | B6: Cancel Plan Open SR on Plan | C6: New | D6: ################# | F6: Mohamed | G6: Bayoumy | H6: mohamed.bayoumy@corp.spdatallc.com | K6: Account Support Merge Accounts | L6: 1
A7: 1011551 | B7: Service Request SR Research/Parts Research | C7: New | D7: ################# | F7: Destany | G7: Greer | H7: Destany.Greer@corp.spdatallc.com | K7: Account Support Other | L7: 13
A8: 1011552 | B8: Web Portal Support Login/Password Support | C8: New | D8: ################# | F8: Destany | G8: Greer | H8: Destany.Greer@corp.spdatallc.com | K8: Billing Update Payment Method | L8: 1
A9: 1007316 | B9: Service Request SR Research/Parts Research | D9: ################# | F9: Anonymous | G9: Anonymous | H9: anonymous | K9: Cancel Plan | L9: 28
A10: 1007489 | B10: Service Request SR Research/Parts Research | D10: ################# | F10: Anonymous | G10: Anonymous | H10: anonymous | K10: Cancel Plan Cancellation Fee Required | L10: 19
A11: 1010396 | B11: Service Request SR Needs to be Cancelled | D11: ################# | F11: Anonymous | G11: Anonymous | H11: anonymous | K11: Cancel Plan Open SR on Plan | L11: 51
A12: 1005263 | B12: Service Request SR Research/Parts Research | D12: ################# | F12: Anonymous | G12: Anonymous | H12: anonymous | K12: Cancel Plan Unable to Service/BER 1st Attempt | L12: 38
A13: 1011383 | B13: Cancel Plan | C13: New | D13: ################# | F13: Colleen | G13: Nash | H13: Colleen.Nash@domesticandgeneral.com | K13: Plan Support Modify/Correct Plan Details | L13: 3
A14: 1011384 | B14: Cancel Plan | C14: New | D14: ################# | F14: Colleen | G14: Nash | H14: Colleen.Nash@domesticandgeneral.com | K14: Plan Support Other | L14: 5
A15: 1011385 | B15: Replacement First Repair BER | C15: New | D15: ################# | F15: Colleen | G15: Nash | H15: Colleen.Nash@domesticandgeneral.com | K15: Replacement Customer Requested Replacement | L15: 2
A16: 1011386 | B16: Cancel Plan Open SR on Plan | C16: New | D16: ################# | F16: Prottasha | G16: Prentice | H16: Prottasha.Prentice@corp.spdatallc.com | K16: Replacement First Repair BER | L16: 4
A17: 1011387 | B17: Cancel Plan Cancellation Fee Required | C17: New | D17: ################# | F17: Kellee | G17: Silva | H17: Kellee.silva@corp.spdatallc.com | K17: Replacement Other | L17: 10
A18: 1011388 | B18: Cancel Plan Unable to Service/BER 1st Attempt | C18: New | D18: ################# | E18: ################# | F18: Maggie | G18: Leon | H18: Maggie.Leon@domesticandgeneral.com | K18: Replacement Subsequent Repair BER | L18: 3
A19: 1011389 | B19: Cancel Plan Unable to Service/BER 1st Attempt | C19: New | D19: ################# | E19: ################# | F19: Maggie | G19: Leon | H19: Maggie.Leon@domesticandgeneral.com | K19: Retention Poor Customer Experience | L19: 4
A20: 1011390 | B20: Cancel Plan Unable to Service/BER 1st Attempt | C20: New | D20: ################# | E20: ################# | F20: Maggie | G20: Leon | H20: Maggie.Leon@domesticandgeneral.com | K20: Sears Repair Authorisation | L20: 5
A21: 1011391 | B21: Replacement Subsequent Repair BER | C21: New | D21: ################# | F21: Colleen | G21: Nash | H21: Colleen.Nash@domesticandgeneral.com | K21: Service Request Confirm Appointment | L21: 2
A22: 1011392 | B22: Cancel Plan | C22: New | D22: ################# | E22: ################# | F22: Colleen | G22: Nash | H22: Colleen.Nash@domesticandgeneral.com | K22: Service Request New SR Needed | L22: 22
A23: 1011184 | B23: Cancel Plan Cancellation Fee Required | C23: New | D23: ################# | F23: Chanetta | G23: Gant | H23: Chanetta.Gant@corp.spdatallc.com | K23: Service Request Out of Network Tech Request | L23: 4
A24: 1011185 | B24: Cancel Plan | C24: New | D24: ################# | F24: Tika | G24: Mayo | H24: Tika.Mayo@corp.spdatallc.com | K24: Service Request Reschedule Request | L24: 6
A25: 1001957 | B25: Account Support Edit/Update Customer Info | C25: In Progress | D25: ################# | F25: Cyn | G25: Holloway | H25: Cynthia.Holloway@domesticandgeneral.com | K25: Service Request SR Needs to be Cancelled | L25: 6
A26: 1008867 | B26: Service Request SR Research/Parts Research | C26: In Progress | D26: ################# | E26: ################# | F26: KAMRY | G26: WILLIAMS | H26: KAMRY.WILLIAMS@domesticandgeneral.com | K26: Service Request SR Research/Parts Research | L26: 29
A27: 1008867 | B27: Service Request SR Research/Parts Research | C27: Pending 7 Day Close | D27: ################# | F27: KAMRY | G27: WILLIAMS | H27: KAMRY.WILLIAMS@domesticandgeneral.com | K27: Web Portal Support Login/Password Support | L27: 24
A28: 1011291 | B28: Cancel Plan Cancellation Fee Required | C28: New | D28: ################# | F28: Michael | G28: Moyer | H28: Michael.Moyer@corp.spdatallc.com | K28: (blank)
A29: 1011292 | B29: Service Request SR Research/Parts Research | C29: New | D29: ################# | F29: Vonceil | G29: Cummings | H29: Vonceil.Cummings@corp.spdatallc.com | K29: Grand Total | L29: 282
A30: 1011293 | B30: Service Request SR Research/Parts Research | C30: New | D30: ################# | F30: John | G30: Allen | H30: john.allen@corp.spdatallc.com
A31: 1011294 | B31: Account Support Other | C31: New | D31: ################# | F31: Stacy | G31: Delaney | H31: Stacy.Delaney@corp.spdatallc.com
A32: 1011295 | B32: Service Request New SR Needed | C32: New | D32: ################# | E32: ################# | F32: Tomekia | G32: Holloway | H32: Tomekia.Casson-Holloway@domesticandgeneral.com
A33: 1011295 | B33: Service Request New SR Needed | C33: In Progress | D33: ################# | E33: ################# | F33: Tomekia | G33: Holloway | H33: Tomekia.Casson-Holloway@domesticandgeneral.com
A34: 1011295 | B34: Service Request New SR Needed | C34: Complaint New | D34: ################# | F34: Tomekia | G34: Holloway | H34: Tomekia.Casson-Holloway@domesticandgeneral.com
A35: 1011296 | B35: Service Request SR Research/Parts Research | C35: New | D35: ################# | F35: Michael | G35: Moyer | H35: Michael.Moyer@corp.spdatallc.com
A36: 1011297 | B36: Replacement Other | C36: New | D36: ################# | F36: John | G36: Allen | H36: john.allen@corp.spdatallc.com
A37: 1011298 | B37: Service Request New SR Needed | C37: New | D37: ################# | F37: Stacy | G37: Delaney | H37: Stacy.Delaney@corp.spdatallc.com
A38: 1011299 | B38: Service Request SR Research/Parts Research | C38: New | D38: ################# | F38: Armelia | G38: Teachey | H38: Armelia.teachey@corp.spdatallc.com
A39: 1011801 | B39: Account Support Bounce Email Follow Up | C39: New | D39: ################# | F39: Michael | G39: Moyer | H39: Michael.Moyer@corp.spdatallc.com
A40: 1011802 | B40: Replacement Customer Requested Replacement | C40: New | D40: ################# | F40: Michael | G40: Moyer | H40: Michael.Moyer@corp.spdatallc.com
...

Sheet BI
A1: BPO | B1: Manager | C1: Plan Selling Agent Name | D1: Agent Type | E1: Primary Skill Score | F1: TelReg Score | G1: Term Indicator | H1: # Campaign Sales | I1: # TelReg IW Sales | J1: # TelReg OOW Sales | K1: # WebReg CC Sales | L1: # WHP CC Sales | M1: # All Sales | N1: # ACH Sales Camp | O1: % ACH Sales All
A2: S&P Cleveland | B2: John Burdett | C2: Alexis Brown | D2: Retention | E2: 0 | F2: 0 | H2: 20 | I2: 9 | J2: 50 | M2: 79 | N2: 59 | O2: 0.747
A3: S&P Cleveland | B3: John Burdett | C3: Amar Ramcharan | D3: Retention | E3: 0 | F3: 0 | H3: 3 | I3: 1 | J3: 8 | M3: 12 | N3: 10 | O3: 0.833
A4: S&P Cleveland | B4: John Burdett | C4: Armelia Teachey | D4: Service | E4: 3 | F4: 0 | H4: 9 | I4: 4 | J4: 22 | M4: 35 | N4: 27 | O4: 0.771
A5: S&P Cleveland | B5: John Burdett | C5: Bhavneet Kaur | D5: Retention | E5: 0 | F5: 0 | H5: 4 | I5: 5 | J5: 16 | M5: 25 | N5: 24 | O5: 0.96
A6: S&P Cleveland | B6: John Burdett | C6: Brianna Totten | D6: Service | E6: 3 | F6: 0 | H6: 1 | I6: 2 | J6: 15 | M6: 18 | N6: 14 | O6: 0.778
A7: S&P Cleveland | B7: John Burdett | C7: Dawn Waisanen | D7: Service | E7: 3 | F7: 0 | H7: 1 | I7: 3 | J7: 8 | M7: 12 | N7: 9 | O7: 0.75
A8: S&P Cleveland | B8: John Burdett | C8: Dessie Temple | D8: Service | E8: 3 | F8: 0 | I8: 2 | J8: 2 | M8: 4 | N8: 4 | O8: 1
A9: S&P Cleveland | B9: John Burdett | C9: Isreal Ojarikreh | D9: Service | E9: 3 | F9: 0 | H9: 16 | I9: 8 | J9: 14 | M9: 38 | N9: 12 | O9: 0.316
A10: S&P Cleveland | B10: John Burdett | C10: Jasmine Riley | D10: Service | E10: 3 | F10: 0 | H10: 2 | J10: 7 | M10: 9 | N10: 3 | O10: 0.333
A11: S&P Cleveland | B11: John Burdett | C11: Jaspreet Kaur | D11: Service | E11: 3 | F11: 0 | H11: 5 | I11: 4 | J11: 24 | M11: 33 | N11: 22 | O11: 0.667
A12: S&P Cleveland | B12: John Burdett | C12: Joshua Ball | D12: Service | E12: 3 | F12: 0 | H12: 1 | I12: 3 | J12: 12 | M12: 16 | N12: 15 | O12: 0.938
A13: S&P Cleveland | B13: John Burdett | C13: Kenneth Bruton | D13: Service | E13: 3 | F13: 0 | H13: 1 | I13: 1 | J13: 23 | M13: 25 | N13: 22 | O13: 0.88
A14: S&P Cleveland | B14: John Burdett | C14: Michael Mcsharry | D14: Service | E14: 3 | F14: 0 | H14: 2 | I14: 6 | J14: 6 | M14: 14 | N14: 10 | O14: 0.714
A15: S&P Cleveland | B15: John Burdett | C15: Michael Parker | D15: Service | E15: 3 | F15: 0 | H15: 10 | I15: 13 | J15: 22 | M15: 45 | N15: 31 | O15: 0.689
A16: S&P Cleveland | B16: John Burdett | C16: Rashaan Little | D16: Service | E16: 3 | F16: 0 | I16: 1 | J16: 17 | M16: 18 | N16: 14 | O16: 0.778
A17: S&P Cleveland | B17: John Burdett | C17: Robert Lampitt | D17: Service | E17: 3 | F17: 0 | H17: 1 | I17: 8 | J17: 11 | M17: 20 | N17: 14 | O17: 0.7
A18: S&P Cleveland | B18: John Burdett | C18: Santhi Katta | D18: Service | E18: 3 | F18: 0 | H18: 3 | I18: 3 | J18: 22 | K18: 1 | M18: 29 | N18: 24 | O18: 0.828
A19: S&P Cleveland | B19: John Burdett | C19: Sharonna Edrington | D19: Service | E19: 3 | F19: 0 | H19: 1 | I19: 2 | J19: 14 | M19: 17 | N19: 9 | O19: 0.529
A20: S&P Cleveland | B20: John Burdett | C20: Vonceil Cummings | D20: Service | E20: 3 | F20: 0 | I20: 2 | J20: 11 | M20: 13 | N20: 4 | O20: 0.308
A21: S&P Cleveland | B21: John Burdett | C21: Yvonne Ndukwu | D21: Service | E21: 3 | F21: 0 | H21: 11 | I21: 5 | J21: 12 | M21: 28 | N21: 15 | O21: 0.536
A22: S&P Cleveland | B22: Nicholas Boudreau | C22: Cassiddy Jordan | D22: Retention | E22: 4 | F22: 0 | H22: 1 | I22: 4 | J22: 13 | M22: 18 | N22: 12 | O22: 0.667
A23: S&P Cleveland | B23: Nicholas Boudreau | C23: Cyndi Fauht | D23: Service | E23: 3 | F23: 0 | I23: 5 | J23: 13 | M23: 18 | N23: 17 | O23: 0.944
A24: S&P Cleveland | B24: Nicholas Boudreau | C24: Destiny Rich | D24: Retention | E24: 4 | F24: 0 | H24: 5 | I24: 3 | J24: 11 | M24: 19 | N24: 8 | O24: 0.421
A25: S&P Cleveland | B25: Nicholas Boudreau | C25: Elizabeth Christian | D25: Retention | E25: 4 | F25: 0 | J25: 3 | M25: 3 | N25: 3 | O25: 1
A26: S&P Cleveland | B26: Nicholas Boudreau | C26: Eric Brown | D26: Retention | E26: 4 | F26: 0 | H26: 1 | I26: 1 | J26: 5 | M26: 7 | N26: 3 | O26: 0.429
A27: S&P Cleveland | B27: Nicholas Boudreau | C27: James Growen | D27: Service | E27: 3 | F27: 0 | H27: 6 | I27: 6 | J27: 8 | M27: 20 | N27: 14 | O27: 0.7
A28: S&P Cleveland | B28: Nicholas Boudreau | C28: Javier Ottenwalder | D28: Retention | E28: 4 | F28: 0 | H28: 11 | I28: 9 | J28: 6 | M28: 26 | N28: 18 | O28: 0.692
A29: S&P Cleveland | B29: Nicholas Boudreau | C29: Kellee Silva | D29: Retention | E29: 4 | F29: 0 | H29: 1 | J29: 8 | M29: 9 | N29: 6 | O29: 0.667
A30: S&P Cleveland | B30: Nicholas Boudreau | C30: Marcia Fabry | D30: Retention | E30: 4 | F30: 0 | H30: 1 | J30: 11 | M30: 12 | N30: 6 | O30: 0.5
A31: S&P Cleveland | B31: Nicholas Boudreau | C31: Michael Moyer | D31: Retention | E31: 4 | F31: 0 | H31: 2 | I31: 3 | J31: 5 | M31: 10 | N31: 6 | O31: 0.6
A32: S&P Cleveland | B32: Nicholas Boudreau | C32: Nirali Patel | D32: Service | E32: 3 | F32: 0 | H32: 2 | I32: 7 | J32: 3 | M32: 12 | N32: 10 | O32: 0.833
A33: S&P Cleveland | B33: Nicholas Boudreau | C33: Prottasha Prentice | D33: Retention | E33: 4 | F33: 0 | I33: 3 | J33: 1 | M33: 4 | N33: 3 | O33: 0.75
A34: S&P Cleveland | B34: Nicholas Boudreau | C34: Shanique Reid | D34: Retention | E34: 4 | F34: 0 | I34: 3 | J34: 18 | M34: 21 | N34: 15 | O34: 0.714
A35: S&P Cleveland | B35: Nicholas Boudreau | C35: Suganya Sabaratnam | D35: Service | E35: 3 | F35: 0 | H35: 3 | I35: 5 | J35: 11 | M35: 19 | N35: 11 | O35: 0.579
A36: S&P Cleveland | B36: Nicholas Boudreau | C36: Tika Mayo | D36: Retention | E36: 4 | F36: 0 | H36: 2 | I36: 5 | J36: 31 | M36: 38 | N36: 20 | O36: 0.526
A37: S&P Cleveland | B37: Nicholas Boudreau | C37: Tina Rogers | D37: Retention | E37: 4 | F37: 0 | J37: 4 | M37: 4 | N37: 2 | O37: 0.5
A38: S&P Cleveland | B38: Nicholas Boudreau | C38: Uniqua Davis | D38: Retention | E38: 4 | F38: 0 | I38: 6 | J38: 11 | M38: 17 | N38: 17 | O38: 1
A39: S&P Cleveland | B39: Reina Morales | C39: Celeste Murph | D39: Service | E39: 3 | F39: 0 | I39: 2 | J39: 15 | M39: 17 | N39: 10 | O39: 0.588
A40: S&P Cleveland | B40: Reina Morales | C40: Christina Harris | D40: Retention | E40: 0 | F40: 0 | I40: 1 | J40: 3 | M40: 4 | N40: 2 | O40: 0.5
...
